[2022-08-18 10:57:30,534] [autoreload.py:637] [autoreload:run_with_reloader] [INFO]- Watching for file changes with StatReloader
[2022-08-18 10:57:33,923] [basehttp.py:161] [basehttp:log_message] [INFO]- "GET / HTTP/1.1" 200 10137
[2022-08-18 10:57:34,267] [views.py:40] [views:counter] [INFO]- response result: {"code": 0, "data": 0}
[2022-08-18 10:57:34,268] [basehttp.py:161] [basehttp:log_message] [INFO]- "GET /api/count HTTP/1.1" 200 22
[2022-08-18 10:57:41,113] [basehttp.py:161] [basehttp:log_message] [INFO]- "GET /polls/addpark/ HTTP/1.1" 200 639
[2022-08-18 10:57:41,175] [log.py:224] [log:log_response] [WARNING]- Not Found: /favicon.ico
[2022-08-18 10:57:41,183] [basehttp.py:161] [basehttp:log_message] [WARNING]- "GET /favicon.ico HTTP/1.1" 404 2451
[2022-08-18 10:57:54,652] [log.py:224] [log:log_response] [ERROR]- Internal Server Error: /polls/addpark/
Traceback (most recent call last):
  File "C:\Users\young\AppData\Local\Programs\Python\Python38\lib\site-packages\django\db\backends\utils.py", line 84, in _execute
    return self.cursor.execute(sql, params)
  File "C:\Users\young\AppData\Local\Programs\Python\Python38\lib\site-packages\django\db\backends\mysql\base.py", line 73, in execute
    return self.cursor.execute(query, args)
  File "C:\Users\young\AppData\Local\Programs\Python\Python38\lib\site-packages\pymysql\cursors.py", line 148, in execute
    result = self._query(query)
  File "C:\Users\young\AppData\Local\Programs\Python\Python38\lib\site-packages\pymysql\cursors.py", line 310, in _query
    conn.query(q)
  File "C:\Users\young\AppData\Local\Programs\Python\Python38\lib\site-packages\pymysql\connections.py", line 548, in query
    self._affected_rows = self._read_query_result(unbuffered=unbuffered)
  File "C:\Users\young\AppData\Local\Programs\Python\Python38\lib\site-packages\pymysql\connections.py", line 775, in _read_query_result
    result.read()
  File "C:\Users\young\AppData\Local\Programs\Python\Python38\lib\site-packages\pymysql\connections.py", line 1156, in read
    first_packet = self.connection._read_packet()
  File "C:\Users\young\AppData\Local\Programs\Python\Python38\lib\site-packages\pymysql\connections.py", line 725, in _read_packet
    packet.raise_for_error()
  File "C:\Users\young\AppData\Local\Programs\Python\Python38\lib\site-packages\pymysql\protocol.py", line 221, in raise_for_error
    err.raise_mysql_exception(self._data)
  File "C:\Users\young\AppData\Local\Programs\Python\Python38\lib\site-packages\pymysql\err.py", line 143, in raise_mysql_exception
    raise errorclass(errno, errval)
pymysql.err.DataError: (1406, "Data too long for column 'introduceEN' at row 1")

The above exception was the direct cause of the following exception:

Traceback (most recent call last):
  File "C:\Users\young\AppData\Local\Programs\Python\Python38\lib\site-packages\django\core\handlers\exception.py", line 47, in inner
    response = get_response(request)
  File "C:\Users\young\AppData\Local\Programs\Python\Python38\lib\site-packages\django\core\handlers\base.py", line 181, in _get_response
    response = wrapped_callback(request, *callback_args, **callback_kwargs)
  File "E:\zl\git-django-qyzs\django_wx_qhzs\polls\views.py", line 152, in add_park
    Park.objects.filter(name1=name1_v).update(naturalLevel=naturalLevel_v, ParkLevel=ParkLevel_v,
  File "C:\Users\young\AppData\Local\Programs\Python\Python38\lib\site-packages\django\db\models\query.py", line 783, in update
    rows = query.get_compiler(self.db).execute_sql(CURSOR)
  File "C:\Users\young\AppData\Local\Programs\Python\Python38\lib\site-packages\django\db\models\sql\compiler.py", line 1559, in execute_sql
    cursor = super().execute_sql(result_type)
  File "C:\Users\young\AppData\Local\Programs\Python\Python38\lib\site-packages\django\db\models\sql\compiler.py", line 1175, in execute_sql
    cursor.execute(sql, params)
  File "C:\Users\young\AppData\Local\Programs\Python\Python38\lib\site-packages\django\db\backends\utils.py", line 98, in execute
    return super().execute(sql, params)
  File "C:\Users\young\AppData\Local\Programs\Python\Python38\lib\site-packages\django\db\backends\utils.py", line 66, in execute
    return self._execute_with_wrappers(sql, params, many=False, executor=self._execute)
  File "C:\Users\young\AppData\Local\Programs\Python\Python38\lib\site-packages\django\db\backends\utils.py", line 75, in _execute_with_wrappers
    return executor(sql, params, many, context)
  File "C:\Users\young\AppData\Local\Programs\Python\Python38\lib\site-packages\django\db\backends\utils.py", line 84, in _execute
    return self.cursor.execute(sql, params)
  File "C:\Users\young\AppData\Local\Programs\Python\Python38\lib\site-packages\django\db\utils.py", line 90, in __exit__
    raise dj_exc_value.with_traceback(traceback) from exc_value
  File "C:\Users\young\AppData\Local\Programs\Python\Python38\lib\site-packages\django\db\backends\utils.py", line 84, in _execute
    return self.cursor.execute(sql, params)
  File "C:\Users\young\AppData\Local\Programs\Python\Python38\lib\site-packages\django\db\backends\mysql\base.py", line 73, in execute
    return self.cursor.execute(query, args)
  File "C:\Users\young\AppData\Local\Programs\Python\Python38\lib\site-packages\pymysql\cursors.py", line 148, in execute
    result = self._query(query)
  File "C:\Users\young\AppData\Local\Programs\Python\Python38\lib\site-packages\pymysql\cursors.py", line 310, in _query
    conn.query(q)
  File "C:\Users\young\AppData\Local\Programs\Python\Python38\lib\site-packages\pymysql\connections.py", line 548, in query
    self._affected_rows = self._read_query_result(unbuffered=unbuffered)
  File "C:\Users\young\AppData\Local\Programs\Python\Python38\lib\site-packages\pymysql\connections.py", line 775, in _read_query_result
    result.read()
  File "C:\Users\young\AppData\Local\Programs\Python\Python38\lib\site-packages\pymysql\connections.py", line 1156, in read
    first_packet = self.connection._read_packet()
  File "C:\Users\young\AppData\Local\Programs\Python\Python38\lib\site-packages\pymysql\connections.py", line 725, in _read_packet
    packet.raise_for_error()
  File "C:\Users\young\AppData\Local\Programs\Python\Python38\lib\site-packages\pymysql\protocol.py", line 221, in raise_for_error
    err.raise_mysql_exception(self._data)
  File "C:\Users\young\AppData\Local\Programs\Python\Python38\lib\site-packages\pymysql\err.py", line 143, in raise_mysql_exception
    raise errorclass(errno, errval)
django.db.utils.DataError: (1406, "Data too long for column 'introduceEN' at row 1")
[2022-08-18 10:57:54,662] [basehttp.py:161] [basehttp:log_message] [ERROR]- "POST /polls/addpark/ HTTP/1.1" 500 291701
[2022-08-18 10:59:11,879] [autoreload.py:637] [autoreload:run_with_reloader] [INFO]- Watching for file changes with StatReloader
[2022-08-18 10:59:14,933] [basehttp.py:161] [basehttp:log_message] [INFO]- "GET / HTTP/1.1" 200 10137
[2022-08-18 10:59:15,230] [views.py:40] [views:counter] [INFO]- response result: {"code": 0, "data": 0}
[2022-08-18 10:59:15,233] [basehttp.py:161] [basehttp:log_message] [INFO]- "GET /api/count HTTP/1.1" 200 22
[2022-08-18 10:59:21,356] [basehttp.py:161] [basehttp:log_message] [INFO]- "GET /polls/addpark/ HTTP/1.1" 200 639
[2022-08-18 10:59:21,435] [log.py:224] [log:log_response] [WARNING]- Not Found: /favicon.ico
[2022-08-18 10:59:21,438] [basehttp.py:161] [basehttp:log_message] [WARNING]- "GET /favicon.ico HTTP/1.1" 404 2451
[2022-08-18 10:59:28,810] [log.py:224] [log:log_response] [ERROR]- Internal Server Error: /polls/addpark/
Traceback (most recent call last):
  File "C:\Users\young\AppData\Local\Programs\Python\Python38\lib\site-packages\django\db\backends\utils.py", line 84, in _execute
    return self.cursor.execute(sql, params)
  File "C:\Users\young\AppData\Local\Programs\Python\Python38\lib\site-packages\django\db\backends\mysql\base.py", line 73, in execute
    return self.cursor.execute(query, args)
  File "C:\Users\young\AppData\Local\Programs\Python\Python38\lib\site-packages\pymysql\cursors.py", line 148, in execute
    result = self._query(query)
  File "C:\Users\young\AppData\Local\Programs\Python\Python38\lib\site-packages\pymysql\cursors.py", line 310, in _query
    conn.query(q)
  File "C:\Users\young\AppData\Local\Programs\Python\Python38\lib\site-packages\pymysql\connections.py", line 548, in query
    self._affected_rows = self._read_query_result(unbuffered=unbuffered)
  File "C:\Users\young\AppData\Local\Programs\Python\Python38\lib\site-packages\pymysql\connections.py", line 775, in _read_query_result
    result.read()
  File "C:\Users\young\AppData\Local\Programs\Python\Python38\lib\site-packages\pymysql\connections.py", line 1156, in read
    first_packet = self.connection._read_packet()
  File "C:\Users\young\AppData\Local\Programs\Python\Python38\lib\site-packages\pymysql\connections.py", line 725, in _read_packet
    packet.raise_for_error()
  File "C:\Users\young\AppData\Local\Programs\Python\Python38\lib\site-packages\pymysql\protocol.py", line 221, in raise_for_error
    err.raise_mysql_exception(self._data)
  File "C:\Users\young\AppData\Local\Programs\Python\Python38\lib\site-packages\pymysql\err.py", line 143, in raise_mysql_exception
    raise errorclass(errno, errval)
pymysql.err.DataError: (1406, "Data too long for column 'introduceEN' at row 1")

The above exception was the direct cause of the following exception:

Traceback (most recent call last):
  File "C:\Users\young\AppData\Local\Programs\Python\Python38\lib\site-packages\django\core\handlers\exception.py", line 47, in inner
    response = get_response(request)
  File "C:\Users\young\AppData\Local\Programs\Python\Python38\lib\site-packages\django\core\handlers\base.py", line 181, in _get_response
    response = wrapped_callback(request, *callback_args, **callback_kwargs)
  File "E:\zl\git-django-qyzs\django_wx_qhzs\polls\views.py", line 152, in add_park
    Park.objects.filter(name1=name1_v).update(naturalLevel=naturalLevel_v, ParkLevel=ParkLevel_v,
  File "C:\Users\young\AppData\Local\Programs\Python\Python38\lib\site-packages\django\db\models\query.py", line 783, in update
    rows = query.get_compiler(self.db).execute_sql(CURSOR)
  File "C:\Users\young\AppData\Local\Programs\Python\Python38\lib\site-packages\django\db\models\sql\compiler.py", line 1559, in execute_sql
    cursor = super().execute_sql(result_type)
  File "C:\Users\young\AppData\Local\Programs\Python\Python38\lib\site-packages\django\db\models\sql\compiler.py", line 1175, in execute_sql
    cursor.execute(sql, params)
  File "C:\Users\young\AppData\Local\Programs\Python\Python38\lib\site-packages\django\db\backends\utils.py", line 98, in execute
    return super().execute(sql, params)
  File "C:\Users\young\AppData\Local\Programs\Python\Python38\lib\site-packages\django\db\backends\utils.py", line 66, in execute
    return self._execute_with_wrappers(sql, params, many=False, executor=self._execute)
  File "C:\Users\young\AppData\Local\Programs\Python\Python38\lib\site-packages\django\db\backends\utils.py", line 75, in _execute_with_wrappers
    return executor(sql, params, many, context)
  File "C:\Users\young\AppData\Local\Programs\Python\Python38\lib\site-packages\django\db\backends\utils.py", line 84, in _execute
    return self.cursor.execute(sql, params)
  File "C:\Users\young\AppData\Local\Programs\Python\Python38\lib\site-packages\django\db\utils.py", line 90, in __exit__
    raise dj_exc_value.with_traceback(traceback) from exc_value
  File "C:\Users\young\AppData\Local\Programs\Python\Python38\lib\site-packages\django\db\backends\utils.py", line 84, in _execute
    return self.cursor.execute(sql, params)
  File "C:\Users\young\AppData\Local\Programs\Python\Python38\lib\site-packages\django\db\backends\mysql\base.py", line 73, in execute
    return self.cursor.execute(query, args)
  File "C:\Users\young\AppData\Local\Programs\Python\Python38\lib\site-packages\pymysql\cursors.py", line 148, in execute
    result = self._query(query)
  File "C:\Users\young\AppData\Local\Programs\Python\Python38\lib\site-packages\pymysql\cursors.py", line 310, in _query
    conn.query(q)
  File "C:\Users\young\AppData\Local\Programs\Python\Python38\lib\site-packages\pymysql\connections.py", line 548, in query
    self._affected_rows = self._read_query_result(unbuffered=unbuffered)
  File "C:\Users\young\AppData\Local\Programs\Python\Python38\lib\site-packages\pymysql\connections.py", line 775, in _read_query_result
    result.read()
  File "C:\Users\young\AppData\Local\Programs\Python\Python38\lib\site-packages\pymysql\connections.py", line 1156, in read
    first_packet = self.connection._read_packet()
  File "C:\Users\young\AppData\Local\Programs\Python\Python38\lib\site-packages\pymysql\connections.py", line 725, in _read_packet
    packet.raise_for_error()
  File "C:\Users\young\AppData\Local\Programs\Python\Python38\lib\site-packages\pymysql\protocol.py", line 221, in raise_for_error
    err.raise_mysql_exception(self._data)
  File "C:\Users\young\AppData\Local\Programs\Python\Python38\lib\site-packages\pymysql\err.py", line 143, in raise_mysql_exception
    raise errorclass(errno, errval)
django.db.utils.DataError: (1406, "Data too long for column 'introduceEN' at row 1")
[2022-08-18 10:59:28,821] [basehttp.py:161] [basehttp:log_message] [ERROR]- "POST /polls/addpark/ HTTP/1.1" 500 291701
[2022-08-18 11:00:46,304] [autoreload.py:251] [autoreload:trigger_reload] [INFO]- E:\zl\git-django-qyzs\django_wx_qhzs\polls\models.py changed, reloading.
[2022-08-18 11:00:47,264] [autoreload.py:637] [autoreload:run_with_reloader] [INFO]- Watching for file changes with StatReloader
[2022-08-18 11:00:50,705] [autoreload.py:251] [autoreload:trigger_reload] [INFO]- E:\zl\git-django-qyzs\django_wx_qhzs\polls\models.py changed, reloading.
[2022-08-18 11:00:51,537] [autoreload.py:637] [autoreload:run_with_reloader] [INFO]- Watching for file changes with StatReloader
[2022-08-18 11:02:04,658] [autoreload.py:637] [autoreload:run_with_reloader] [INFO]- Watching for file changes with StatReloader
[2022-08-18 11:02:11,135] [basehttp.py:161] [basehttp:log_message] [INFO]- "GET /polls/addpark/ HTTP/1.1" 200 639
[2022-08-18 11:02:14,983] [log.py:224] [log:log_response] [ERROR]- Internal Server Error: /polls/addpark/
Traceback (most recent call last):
  File "C:\Users\young\AppData\Local\Programs\Python\Python38\lib\site-packages\django\db\backends\utils.py", line 84, in _execute
    return self.cursor.execute(sql, params)
  File "C:\Users\young\AppData\Local\Programs\Python\Python38\lib\site-packages\django\db\backends\mysql\base.py", line 73, in execute
    return self.cursor.execute(query, args)
  File "C:\Users\young\AppData\Local\Programs\Python\Python38\lib\site-packages\pymysql\cursors.py", line 148, in execute
    result = self._query(query)
  File "C:\Users\young\AppData\Local\Programs\Python\Python38\lib\site-packages\pymysql\cursors.py", line 310, in _query
    conn.query(q)
  File "C:\Users\young\AppData\Local\Programs\Python\Python38\lib\site-packages\pymysql\connections.py", line 548, in query
    self._affected_rows = self._read_query_result(unbuffered=unbuffered)
  File "C:\Users\young\AppData\Local\Programs\Python\Python38\lib\site-packages\pymysql\connections.py", line 775, in _read_query_result
    result.read()
  File "C:\Users\young\AppData\Local\Programs\Python\Python38\lib\site-packages\pymysql\connections.py", line 1156, in read
    first_packet = self.connection._read_packet()
  File "C:\Users\young\AppData\Local\Programs\Python\Python38\lib\site-packages\pymysql\connections.py", line 725, in _read_packet
    packet.raise_for_error()
  File "C:\Users\young\AppData\Local\Programs\Python\Python38\lib\site-packages\pymysql\protocol.py", line 221, in raise_for_error
    err.raise_mysql_exception(self._data)
  File "C:\Users\young\AppData\Local\Programs\Python\Python38\lib\site-packages\pymysql\err.py", line 143, in raise_mysql_exception
    raise errorclass(errno, errval)
pymysql.err.DataError: (1406, "Data too long for column 'introduceEN' at row 1")

The above exception was the direct cause of the following exception:

Traceback (most recent call last):
  File "C:\Users\young\AppData\Local\Programs\Python\Python38\lib\site-packages\django\core\handlers\exception.py", line 47, in inner
    response = get_response(request)
  File "C:\Users\young\AppData\Local\Programs\Python\Python38\lib\site-packages\django\core\handlers\base.py", line 181, in _get_response
    response = wrapped_callback(request, *callback_args, **callback_kwargs)
  File "E:\zl\git-django-qyzs\django_wx_qhzs\polls\views.py", line 152, in add_park
    Park.objects.filter(name1=name1_v).update(naturalLevel=naturalLevel_v, ParkLevel=ParkLevel_v,
  File "C:\Users\young\AppData\Local\Programs\Python\Python38\lib\site-packages\django\db\models\query.py", line 783, in update
    rows = query.get_compiler(self.db).execute_sql(CURSOR)
  File "C:\Users\young\AppData\Local\Programs\Python\Python38\lib\site-packages\django\db\models\sql\compiler.py", line 1559, in execute_sql
    cursor = super().execute_sql(result_type)
  File "C:\Users\young\AppData\Local\Programs\Python\Python38\lib\site-packages\django\db\models\sql\compiler.py", line 1175, in execute_sql
    cursor.execute(sql, params)
  File "C:\Users\young\AppData\Local\Programs\Python\Python38\lib\site-packages\django\db\backends\utils.py", line 98, in execute
    return super().execute(sql, params)
  File "C:\Users\young\AppData\Local\Programs\Python\Python38\lib\site-packages\django\db\backends\utils.py", line 66, in execute
    return self._execute_with_wrappers(sql, params, many=False, executor=self._execute)
  File "C:\Users\young\AppData\Local\Programs\Python\Python38\lib\site-packages\django\db\backends\utils.py", line 75, in _execute_with_wrappers
    return executor(sql, params, many, context)
  File "C:\Users\young\AppData\Local\Programs\Python\Python38\lib\site-packages\django\db\backends\utils.py", line 84, in _execute
    return self.cursor.execute(sql, params)
  File "C:\Users\young\AppData\Local\Programs\Python\Python38\lib\site-packages\django\db\utils.py", line 90, in __exit__
    raise dj_exc_value.with_traceback(traceback) from exc_value
  File "C:\Users\young\AppData\Local\Programs\Python\Python38\lib\site-packages\django\db\backends\utils.py", line 84, in _execute
    return self.cursor.execute(sql, params)
  File "C:\Users\young\AppData\Local\Programs\Python\Python38\lib\site-packages\django\db\backends\mysql\base.py", line 73, in execute
    return self.cursor.execute(query, args)
  File "C:\Users\young\AppData\Local\Programs\Python\Python38\lib\site-packages\pymysql\cursors.py", line 148, in execute
    result = self._query(query)
  File "C:\Users\young\AppData\Local\Programs\Python\Python38\lib\site-packages\pymysql\cursors.py", line 310, in _query
    conn.query(q)
  File "C:\Users\young\AppData\Local\Programs\Python\Python38\lib\site-packages\pymysql\connections.py", line 548, in query
    self._affected_rows = self._read_query_result(unbuffered=unbuffered)
  File "C:\Users\young\AppData\Local\Programs\Python\Python38\lib\site-packages\pymysql\connections.py", line 775, in _read_query_result
    result.read()
  File "C:\Users\young\AppData\Local\Programs\Python\Python38\lib\site-packages\pymysql\connections.py", line 1156, in read
    first_packet = self.connection._read_packet()
  File "C:\Users\young\AppData\Local\Programs\Python\Python38\lib\site-packages\pymysql\connections.py", line 725, in _read_packet
    packet.raise_for_error()
  File "C:\Users\young\AppData\Local\Programs\Python\Python38\lib\site-packages\pymysql\protocol.py", line 221, in raise_for_error
    err.raise_mysql_exception(self._data)
  File "C:\Users\young\AppData\Local\Programs\Python\Python38\lib\site-packages\pymysql\err.py", line 143, in raise_mysql_exception
    raise errorclass(errno, errval)
django.db.utils.DataError: (1406, "Data too long for column 'introduceEN' at row 1")
[2022-08-18 11:02:14,996] [basehttp.py:161] [basehttp:log_message] [ERROR]- "POST /polls/addpark/ HTTP/1.1" 500 291701
[2022-08-18 11:04:48,440] [autoreload.py:637] [autoreload:run_with_reloader] [INFO]- Watching for file changes with StatReloader
[2022-08-18 11:08:47,294] [autoreload.py:637] [autoreload:run_with_reloader] [INFO]- Watching for file changes with StatReloader
[2022-08-18 11:08:49,578] [basehttp.py:161] [basehttp:log_message] [INFO]- "GET / HTTP/1.1" 200 10137
[2022-08-18 11:08:49,852] [views.py:40] [views:counter] [INFO]- response result: {"code": 0, "data": 0}
[2022-08-18 11:08:49,853] [basehttp.py:161] [basehttp:log_message] [INFO]- "GET /api/count HTTP/1.1" 200 22
[2022-08-18 11:09:13,360] [basehttp.py:161] [basehttp:log_message] [INFO]- "GET /polls/addpark/ HTTP/1.1" 200 639
[2022-08-18 11:09:13,554] [log.py:224] [log:log_response] [WARNING]- Not Found: /favicon.ico
[2022-08-18 11:09:13,555] [basehttp.py:161] [basehttp:log_message] [WARNING]- "GET /favicon.ico HTTP/1.1" 404 2451
[2022-08-18 11:09:17,992] [log.py:224] [log:log_response] [ERROR]- Internal Server Error: /polls/addpark/
Traceback (most recent call last):
  File "C:\Users\young\AppData\Local\Programs\Python\Python38\lib\site-packages\django\db\backends\utils.py", line 84, in _execute
    return self.cursor.execute(sql, params)
  File "C:\Users\young\AppData\Local\Programs\Python\Python38\lib\site-packages\django\db\backends\mysql\base.py", line 73, in execute
    return self.cursor.execute(query, args)
  File "C:\Users\young\AppData\Local\Programs\Python\Python38\lib\site-packages\pymysql\cursors.py", line 148, in execute
    result = self._query(query)
  File "C:\Users\young\AppData\Local\Programs\Python\Python38\lib\site-packages\pymysql\cursors.py", line 310, in _query
    conn.query(q)
  File "C:\Users\young\AppData\Local\Programs\Python\Python38\lib\site-packages\pymysql\connections.py", line 548, in query
    self._affected_rows = self._read_query_result(unbuffered=unbuffered)
  File "C:\Users\young\AppData\Local\Programs\Python\Python38\lib\site-packages\pymysql\connections.py", line 775, in _read_query_result
    result.read()
  File "C:\Users\young\AppData\Local\Programs\Python\Python38\lib\site-packages\pymysql\connections.py", line 1156, in read
    first_packet = self.connection._read_packet()
  File "C:\Users\young\AppData\Local\Programs\Python\Python38\lib\site-packages\pymysql\connections.py", line 725, in _read_packet
    packet.raise_for_error()
  File "C:\Users\young\AppData\Local\Programs\Python\Python38\lib\site-packages\pymysql\protocol.py", line 221, in raise_for_error
    err.raise_mysql_exception(self._data)
  File "C:\Users\young\AppData\Local\Programs\Python\Python38\lib\site-packages\pymysql\err.py", line 143, in raise_mysql_exception
    raise errorclass(errno, errval)
pymysql.err.DataError: (1406, "Data too long for column 'abbreviation' at row 1")

The above exception was the direct cause of the following exception:

Traceback (most recent call last):
  File "C:\Users\young\AppData\Local\Programs\Python\Python38\lib\site-packages\django\core\handlers\exception.py", line 47, in inner
    response = get_response(request)
  File "C:\Users\young\AppData\Local\Programs\Python\Python38\lib\site-packages\django\core\handlers\base.py", line 181, in _get_response
    response = wrapped_callback(request, *callback_args, **callback_kwargs)
  File "E:\zl\git-django-qyzs\django_wx_qhzs\polls\views.py", line 140, in add_park
    Park.objects.create(naturalLevel=naturalLevel_v, ParkLevel=ParkLevel_v,
  File "C:\Users\young\AppData\Local\Programs\Python\Python38\lib\site-packages\django\db\models\manager.py", line 85, in manager_method
    return getattr(self.get_queryset(), name)(*args, **kwargs)
  File "C:\Users\young\AppData\Local\Programs\Python\Python38\lib\site-packages\django\db\models\query.py", line 453, in create
    obj.save(force_insert=True, using=self.db)
  File "C:\Users\young\AppData\Local\Programs\Python\Python38\lib\site-packages\django\db\models\base.py", line 739, in save
    self.save_base(using=using, force_insert=force_insert,
  File "C:\Users\young\AppData\Local\Programs\Python\Python38\lib\site-packages\django\db\models\base.py", line 776, in save_base
    updated = self._save_table(
  File "C:\Users\young\AppData\Local\Programs\Python\Python38\lib\site-packages\django\db\models\base.py", line 881, in _save_table
    results = self._do_insert(cls._base_manager, using, fields, returning_fields, raw)
  File "C:\Users\young\AppData\Local\Programs\Python\Python38\lib\site-packages\django\db\models\base.py", line 919, in _do_insert
    return manager._insert(
  File "C:\Users\young\AppData\Local\Programs\Python\Python38\lib\site-packages\django\db\models\manager.py", line 85, in manager_method
    return getattr(self.get_queryset(), name)(*args, **kwargs)
  File "C:\Users\young\AppData\Local\Programs\Python\Python38\lib\site-packages\django\db\models\query.py", line 1270, in _insert
    return query.get_compiler(using=using).execute_sql(returning_fields)
  File "C:\Users\young\AppData\Local\Programs\Python\Python38\lib\site-packages\django\db\models\sql\compiler.py", line 1416, in execute_sql
    cursor.execute(sql, params)
  File "C:\Users\young\AppData\Local\Programs\Python\Python38\lib\site-packages\django\db\backends\utils.py", line 98, in execute
    return super().execute(sql, params)
  File "C:\Users\young\AppData\Local\Programs\Python\Python38\lib\site-packages\django\db\backends\utils.py", line 66, in execute
    return self._execute_with_wrappers(sql, params, many=False, executor=self._execute)
  File "C:\Users\young\AppData\Local\Programs\Python\Python38\lib\site-packages\django\db\backends\utils.py", line 75, in _execute_with_wrappers
    return executor(sql, params, many, context)
  File "C:\Users\young\AppData\Local\Programs\Python\Python38\lib\site-packages\django\db\backends\utils.py", line 84, in _execute
    return self.cursor.execute(sql, params)
  File "C:\Users\young\AppData\Local\Programs\Python\Python38\lib\site-packages\django\db\utils.py", line 90, in __exit__
    raise dj_exc_value.with_traceback(traceback) from exc_value
  File "C:\Users\young\AppData\Local\Programs\Python\Python38\lib\site-packages\django\db\backends\utils.py", line 84, in _execute
    return self.cursor.execute(sql, params)
  File "C:\Users\young\AppData\Local\Programs\Python\Python38\lib\site-packages\django\db\backends\mysql\base.py", line 73, in execute
    return self.cursor.execute(query, args)
  File "C:\Users\young\AppData\Local\Programs\Python\Python38\lib\site-packages\pymysql\cursors.py", line 148, in execute
    result = self._query(query)
  File "C:\Users\young\AppData\Local\Programs\Python\Python38\lib\site-packages\pymysql\cursors.py", line 310, in _query
    conn.query(q)
  File "C:\Users\young\AppData\Local\Programs\Python\Python38\lib\site-packages\pymysql\connections.py", line 548, in query
    self._affected_rows = self._read_query_result(unbuffered=unbuffered)
  File "C:\Users\young\AppData\Local\Programs\Python\Python38\lib\site-packages\pymysql\connections.py", line 775, in _read_query_result
    result.read()
  File "C:\Users\young\AppData\Local\Programs\Python\Python38\lib\site-packages\pymysql\connections.py", line 1156, in read
    first_packet = self.connection._read_packet()
  File "C:\Users\young\AppData\Local\Programs\Python\Python38\lib\site-packages\pymysql\connections.py", line 725, in _read_packet
    packet.raise_for_error()
  File "C:\Users\young\AppData\Local\Programs\Python\Python38\lib\site-packages\pymysql\protocol.py", line 221, in raise_for_error
    err.raise_mysql_exception(self._data)
  File "C:\Users\young\AppData\Local\Programs\Python\Python38\lib\site-packages\pymysql\err.py", line 143, in raise_mysql_exception
    raise errorclass(errno, errval)
django.db.utils.DataError: (1406, "Data too long for column 'abbreviation' at row 1")
[2022-08-18 11:09:18,022] [basehttp.py:161] [basehttp:log_message] [ERROR]- "POST /polls/addpark/ HTTP/1.1" 500 332557
[2022-08-18 11:10:54,762] [autoreload.py:637] [autoreload:run_with_reloader] [INFO]- Watching for file changes with StatReloader
[2022-08-18 11:11:54,957] [autoreload.py:637] [autoreload:run_with_reloader] [INFO]- Watching for file changes with StatReloader
[2022-08-18 11:12:47,884] [autoreload.py:637] [autoreload:run_with_reloader] [INFO]- Watching for file changes with StatReloader
[2022-08-18 11:13:17,275] [basehttp.py:161] [basehttp:log_message] [INFO]- "GET /polls/addpark/ HTTP/1.1" 200 639
[2022-08-18 11:13:21,071] [log.py:224] [log:log_response] [ERROR]- Internal Server Error: /polls/addpark/
Traceback (most recent call last):
  File "C:\Users\young\AppData\Local\Programs\Python\Python38\lib\site-packages\django\db\backends\utils.py", line 84, in _execute
    return self.cursor.execute(sql, params)
  File "C:\Users\young\AppData\Local\Programs\Python\Python38\lib\site-packages\django\db\backends\mysql\base.py", line 73, in execute
    return self.cursor.execute(query, args)
  File "C:\Users\young\AppData\Local\Programs\Python\Python38\lib\site-packages\pymysql\cursors.py", line 148, in execute
    result = self._query(query)
  File "C:\Users\young\AppData\Local\Programs\Python\Python38\lib\site-packages\pymysql\cursors.py", line 310, in _query
    conn.query(q)
  File "C:\Users\young\AppData\Local\Programs\Python\Python38\lib\site-packages\pymysql\connections.py", line 548, in query
    self._affected_rows = self._read_query_result(unbuffered=unbuffered)
  File "C:\Users\young\AppData\Local\Programs\Python\Python38\lib\site-packages\pymysql\connections.py", line 775, in _read_query_result
    result.read()
  File "C:\Users\young\AppData\Local\Programs\Python\Python38\lib\site-packages\pymysql\connections.py", line 1156, in read
    first_packet = self.connection._read_packet()
  File "C:\Users\young\AppData\Local\Programs\Python\Python38\lib\site-packages\pymysql\connections.py", line 725, in _read_packet
    packet.raise_for_error()
  File "C:\Users\young\AppData\Local\Programs\Python\Python38\lib\site-packages\pymysql\protocol.py", line 221, in raise_for_error
    err.raise_mysql_exception(self._data)
  File "C:\Users\young\AppData\Local\Programs\Python\Python38\lib\site-packages\pymysql\err.py", line 143, in raise_mysql_exception
    raise errorclass(errno, errval)
pymysql.err.DataError: (1406, "Data too long for column 'abbreviation' at row 1")

The above exception was the direct cause of the following exception:

Traceback (most recent call last):
  File "C:\Users\young\AppData\Local\Programs\Python\Python38\lib\site-packages\django\core\handlers\exception.py", line 47, in inner
    response = get_response(request)
  File "C:\Users\young\AppData\Local\Programs\Python\Python38\lib\site-packages\django\core\handlers\base.py", line 181, in _get_response
    response = wrapped_callback(request, *callback_args, **callback_kwargs)
  File "E:\zl\git-django-qyzs\django_wx_qhzs\polls\views.py", line 140, in add_park
    Park.objects.create(naturalLevel=naturalLevel_v, ParkLevel=ParkLevel_v,
  File "C:\Users\young\AppData\Local\Programs\Python\Python38\lib\site-packages\django\db\models\manager.py", line 85, in manager_method
    return getattr(self.get_queryset(), name)(*args, **kwargs)
  File "C:\Users\young\AppData\Local\Programs\Python\Python38\lib\site-packages\django\db\models\query.py", line 453, in create
    obj.save(force_insert=True, using=self.db)
  File "C:\Users\young\AppData\Local\Programs\Python\Python38\lib\site-packages\django\db\models\base.py", line 739, in save
    self.save_base(using=using, force_insert=force_insert,
  File "C:\Users\young\AppData\Local\Programs\Python\Python38\lib\site-packages\django\db\models\base.py", line 776, in save_base
    updated = self._save_table(
  File "C:\Users\young\AppData\Local\Programs\Python\Python38\lib\site-packages\django\db\models\base.py", line 881, in _save_table
    results = self._do_insert(cls._base_manager, using, fields, returning_fields, raw)
  File "C:\Users\young\AppData\Local\Programs\Python\Python38\lib\site-packages\django\db\models\base.py", line 919, in _do_insert
    return manager._insert(
  File "C:\Users\young\AppData\Local\Programs\Python\Python38\lib\site-packages\django\db\models\manager.py", line 85, in manager_method
    return getattr(self.get_queryset(), name)(*args, **kwargs)
  File "C:\Users\young\AppData\Local\Programs\Python\Python38\lib\site-packages\django\db\models\query.py", line 1270, in _insert
    return query.get_compiler(using=using).execute_sql(returning_fields)
  File "C:\Users\young\AppData\Local\Programs\Python\Python38\lib\site-packages\django\db\models\sql\compiler.py", line 1416, in execute_sql
    cursor.execute(sql, params)
  File "C:\Users\young\AppData\Local\Programs\Python\Python38\lib\site-packages\django\db\backends\utils.py", line 98, in execute
    return super().execute(sql, params)
  File "C:\Users\young\AppData\Local\Programs\Python\Python38\lib\site-packages\django\db\backends\utils.py", line 66, in execute
    return self._execute_with_wrappers(sql, params, many=False, executor=self._execute)
  File "C:\Users\young\AppData\Local\Programs\Python\Python38\lib\site-packages\django\db\backends\utils.py", line 75, in _execute_with_wrappers
    return executor(sql, params, many, context)
  File "C:\Users\young\AppData\Local\Programs\Python\Python38\lib\site-packages\django\db\backends\utils.py", line 84, in _execute
    return self.cursor.execute(sql, params)
  File "C:\Users\young\AppData\Local\Programs\Python\Python38\lib\site-packages\django\db\utils.py", line 90, in __exit__
    raise dj_exc_value.with_traceback(traceback) from exc_value
  File "C:\Users\young\AppData\Local\Programs\Python\Python38\lib\site-packages\django\db\backends\utils.py", line 84, in _execute
    return self.cursor.execute(sql, params)
  File "C:\Users\young\AppData\Local\Programs\Python\Python38\lib\site-packages\django\db\backends\mysql\base.py", line 73, in execute
    return self.cursor.execute(query, args)
  File "C:\Users\young\AppData\Local\Programs\Python\Python38\lib\site-packages\pymysql\cursors.py", line 148, in execute
    result = self._query(query)
  File "C:\Users\young\AppData\Local\Programs\Python\Python38\lib\site-packages\pymysql\cursors.py", line 310, in _query
    conn.query(q)
  File "C:\Users\young\AppData\Local\Programs\Python\Python38\lib\site-packages\pymysql\connections.py", line 548, in query
    self._affected_rows = self._read_query_result(unbuffered=unbuffered)
  File "C:\Users\young\AppData\Local\Programs\Python\Python38\lib\site-packages\pymysql\connections.py", line 775, in _read_query_result
    result.read()
  File "C:\Users\young\AppData\Local\Programs\Python\Python38\lib\site-packages\pymysql\connections.py", line 1156, in read
    first_packet = self.connection._read_packet()
  File "C:\Users\young\AppData\Local\Programs\Python\Python38\lib\site-packages\pymysql\connections.py", line 725, in _read_packet
    packet.raise_for_error()
  File "C:\Users\young\AppData\Local\Programs\Python\Python38\lib\site-packages\pymysql\protocol.py", line 221, in raise_for_error
    err.raise_mysql_exception(self._data)
  File "C:\Users\young\AppData\Local\Programs\Python\Python38\lib\site-packages\pymysql\err.py", line 143, in raise_mysql_exception
    raise errorclass(errno, errval)
django.db.utils.DataError: (1406, "Data too long for column 'abbreviation' at row 1")
[2022-08-18 11:13:21,087] [basehttp.py:161] [basehttp:log_message] [ERROR]- "POST /polls/addpark/ HTTP/1.1" 500 332557
[2022-08-18 11:22:32,561] [basehttp.py:161] [basehttp:log_message] [INFO]- "GET /polls/addpark/ HTTP/1.1" 200 639
[2022-08-18 11:22:36,760] [log.py:224] [log:log_response] [ERROR]- Internal Server Error: /polls/addpark/
Traceback (most recent call last):
  File "C:\Users\young\AppData\Local\Programs\Python\Python38\lib\site-packages\django\db\backends\utils.py", line 84, in _execute
    return self.cursor.execute(sql, params)
  File "C:\Users\young\AppData\Local\Programs\Python\Python38\lib\site-packages\django\db\backends\mysql\base.py", line 73, in execute
    return self.cursor.execute(query, args)
  File "C:\Users\young\AppData\Local\Programs\Python\Python38\lib\site-packages\pymysql\cursors.py", line 148, in execute
    result = self._query(query)
  File "C:\Users\young\AppData\Local\Programs\Python\Python38\lib\site-packages\pymysql\cursors.py", line 310, in _query
    conn.query(q)
  File "C:\Users\young\AppData\Local\Programs\Python\Python38\lib\site-packages\pymysql\connections.py", line 548, in query
    self._affected_rows = self._read_query_result(unbuffered=unbuffered)
  File "C:\Users\young\AppData\Local\Programs\Python\Python38\lib\site-packages\pymysql\connections.py", line 775, in _read_query_result
    result.read()
  File "C:\Users\young\AppData\Local\Programs\Python\Python38\lib\site-packages\pymysql\connections.py", line 1156, in read
    first_packet = self.connection._read_packet()
  File "C:\Users\young\AppData\Local\Programs\Python\Python38\lib\site-packages\pymysql\connections.py", line 725, in _read_packet
    packet.raise_for_error()
  File "C:\Users\young\AppData\Local\Programs\Python\Python38\lib\site-packages\pymysql\protocol.py", line 221, in raise_for_error
    err.raise_mysql_exception(self._data)
  File "C:\Users\young\AppData\Local\Programs\Python\Python38\lib\site-packages\pymysql\err.py", line 143, in raise_mysql_exception
    raise errorclass(errno, errval)
pymysql.err.DataError: (1406, "Data too long for column 'abbreviation' at row 1")

The above exception was the direct cause of the following exception:

Traceback (most recent call last):
  File "C:\Users\young\AppData\Local\Programs\Python\Python38\lib\site-packages\django\core\handlers\exception.py", line 47, in inner
    response = get_response(request)
  File "C:\Users\young\AppData\Local\Programs\Python\Python38\lib\site-packages\django\core\handlers\base.py", line 181, in _get_response
    response = wrapped_callback(request, *callback_args, **callback_kwargs)
  File "E:\zl\git-django-qyzs\django_wx_qhzs\polls\views.py", line 140, in add_park
    Park.objects.create(naturalLevel=naturalLevel_v, ParkLevel=ParkLevel_v,
  File "C:\Users\young\AppData\Local\Programs\Python\Python38\lib\site-packages\django\db\models\manager.py", line 85, in manager_method
    return getattr(self.get_queryset(), name)(*args, **kwargs)
  File "C:\Users\young\AppData\Local\Programs\Python\Python38\lib\site-packages\django\db\models\query.py", line 453, in create
    obj.save(force_insert=True, using=self.db)
  File "C:\Users\young\AppData\Local\Programs\Python\Python38\lib\site-packages\django\db\models\base.py", line 739, in save
    self.save_base(using=using, force_insert=force_insert,
  File "C:\Users\young\AppData\Local\Programs\Python\Python38\lib\site-packages\django\db\models\base.py", line 776, in save_base
    updated = self._save_table(
  File "C:\Users\young\AppData\Local\Programs\Python\Python38\lib\site-packages\django\db\models\base.py", line 881, in _save_table
    results = self._do_insert(cls._base_manager, using, fields, returning_fields, raw)
  File "C:\Users\young\AppData\Local\Programs\Python\Python38\lib\site-packages\django\db\models\base.py", line 919, in _do_insert
    return manager._insert(
  File "C:\Users\young\AppData\Local\Programs\Python\Python38\lib\site-packages\django\db\models\manager.py", line 85, in manager_method
    return getattr(self.get_queryset(), name)(*args, **kwargs)
  File "C:\Users\young\AppData\Local\Programs\Python\Python38\lib\site-packages\django\db\models\query.py", line 1270, in _insert
    return query.get_compiler(using=using).execute_sql(returning_fields)
  File "C:\Users\young\AppData\Local\Programs\Python\Python38\lib\site-packages\django\db\models\sql\compiler.py", line 1416, in execute_sql
    cursor.execute(sql, params)
  File "C:\Users\young\AppData\Local\Programs\Python\Python38\lib\site-packages\django\db\backends\utils.py", line 98, in execute
    return super().execute(sql, params)
  File "C:\Users\young\AppData\Local\Programs\Python\Python38\lib\site-packages\django\db\backends\utils.py", line 66, in execute
    return self._execute_with_wrappers(sql, params, many=False, executor=self._execute)
  File "C:\Users\young\AppData\Local\Programs\Python\Python38\lib\site-packages\django\db\backends\utils.py", line 75, in _execute_with_wrappers
    return executor(sql, params, many, context)
  File "C:\Users\young\AppData\Local\Programs\Python\Python38\lib\site-packages\django\db\backends\utils.py", line 84, in _execute
    return self.cursor.execute(sql, params)
  File "C:\Users\young\AppData\Local\Programs\Python\Python38\lib\site-packages\django\db\utils.py", line 90, in __exit__
    raise dj_exc_value.with_traceback(traceback) from exc_value
  File "C:\Users\young\AppData\Local\Programs\Python\Python38\lib\site-packages\django\db\backends\utils.py", line 84, in _execute
    return self.cursor.execute(sql, params)
  File "C:\Users\young\AppData\Local\Programs\Python\Python38\lib\site-packages\django\db\backends\mysql\base.py", line 73, in execute
    return self.cursor.execute(query, args)
  File "C:\Users\young\AppData\Local\Programs\Python\Python38\lib\site-packages\pymysql\cursors.py", line 148, in execute
    result = self._query(query)
  File "C:\Users\young\AppData\Local\Programs\Python\Python38\lib\site-packages\pymysql\cursors.py", line 310, in _query
    conn.query(q)
  File "C:\Users\young\AppData\Local\Programs\Python\Python38\lib\site-packages\pymysql\connections.py", line 548, in query
    self._affected_rows = self._read_query_result(unbuffered=unbuffered)
  File "C:\Users\young\AppData\Local\Programs\Python\Python38\lib\site-packages\pymysql\connections.py", line 775, in _read_query_result
    result.read()
  File "C:\Users\young\AppData\Local\Programs\Python\Python38\lib\site-packages\pymysql\connections.py", line 1156, in read
    first_packet = self.connection._read_packet()
  File "C:\Users\young\AppData\Local\Programs\Python\Python38\lib\site-packages\pymysql\connections.py", line 725, in _read_packet
    packet.raise_for_error()
  File "C:\Users\young\AppData\Local\Programs\Python\Python38\lib\site-packages\pymysql\protocol.py", line 221, in raise_for_error
    err.raise_mysql_exception(self._data)
  File "C:\Users\young\AppData\Local\Programs\Python\Python38\lib\site-packages\pymysql\err.py", line 143, in raise_mysql_exception
    raise errorclass(errno, errval)
django.db.utils.DataError: (1406, "Data too long for column 'abbreviation' at row 1")
[2022-08-18 11:22:36,780] [basehttp.py:161] [basehttp:log_message] [ERROR]- "POST /polls/addpark/ HTTP/1.1" 500 332557
[2022-08-18 11:23:42,898] [autoreload.py:251] [autoreload:trigger_reload] [INFO]- E:\zl\git-django-qyzs\django_wx_qhzs\polls\models.py changed, reloading.
[2022-08-18 11:23:43,851] [autoreload.py:637] [autoreload:run_with_reloader] [INFO]- Watching for file changes with StatReloader
[2022-08-18 11:24:19,848] [autoreload.py:637] [autoreload:run_with_reloader] [INFO]- Watching for file changes with StatReloader
[2022-08-18 11:24:45,722] [basehttp.py:161] [basehttp:log_message] [INFO]- "GET /polls/addpark/ HTTP/1.1" 200 639
[2022-08-18 11:24:49,852] [log.py:224] [log:log_response] [ERROR]- Internal Server Error: /polls/addpark/
Traceback (most recent call last):
  File "C:\Users\young\AppData\Local\Programs\Python\Python38\lib\site-packages\django\db\backends\utils.py", line 84, in _execute
    return self.cursor.execute(sql, params)
  File "C:\Users\young\AppData\Local\Programs\Python\Python38\lib\site-packages\django\db\backends\mysql\base.py", line 73, in execute
    return self.cursor.execute(query, args)
  File "C:\Users\young\AppData\Local\Programs\Python\Python38\lib\site-packages\pymysql\cursors.py", line 148, in execute
    result = self._query(query)
  File "C:\Users\young\AppData\Local\Programs\Python\Python38\lib\site-packages\pymysql\cursors.py", line 310, in _query
    conn.query(q)
  File "C:\Users\young\AppData\Local\Programs\Python\Python38\lib\site-packages\pymysql\connections.py", line 548, in query
    self._affected_rows = self._read_query_result(unbuffered=unbuffered)
  File "C:\Users\young\AppData\Local\Programs\Python\Python38\lib\site-packages\pymysql\connections.py", line 775, in _read_query_result
    result.read()
  File "C:\Users\young\AppData\Local\Programs\Python\Python38\lib\site-packages\pymysql\connections.py", line 1156, in read
    first_packet = self.connection._read_packet()
  File "C:\Users\young\AppData\Local\Programs\Python\Python38\lib\site-packages\pymysql\connections.py", line 725, in _read_packet
    packet.raise_for_error()
  File "C:\Users\young\AppData\Local\Programs\Python\Python38\lib\site-packages\pymysql\protocol.py", line 221, in raise_for_error
    err.raise_mysql_exception(self._data)
  File "C:\Users\young\AppData\Local\Programs\Python\Python38\lib\site-packages\pymysql\err.py", line 143, in raise_mysql_exception
    raise errorclass(errno, errval)
pymysql.err.DataError: (1406, "Data too long for column 'abbreviation' at row 1")

The above exception was the direct cause of the following exception:

Traceback (most recent call last):
  File "C:\Users\young\AppData\Local\Programs\Python\Python38\lib\site-packages\django\core\handlers\exception.py", line 47, in inner
    response = get_response(request)
  File "C:\Users\young\AppData\Local\Programs\Python\Python38\lib\site-packages\django\core\handlers\base.py", line 181, in _get_response
    response = wrapped_callback(request, *callback_args, **callback_kwargs)
  File "E:\zl\git-django-qyzs\django_wx_qhzs\polls\views.py", line 140, in add_park
    Park.objects.create(naturalLevel=naturalLevel_v, ParkLevel=ParkLevel_v,
  File "C:\Users\young\AppData\Local\Programs\Python\Python38\lib\site-packages\django\db\models\manager.py", line 85, in manager_method
    return getattr(self.get_queryset(), name)(*args, **kwargs)
  File "C:\Users\young\AppData\Local\Programs\Python\Python38\lib\site-packages\django\db\models\query.py", line 453, in create
    obj.save(force_insert=True, using=self.db)
  File "C:\Users\young\AppData\Local\Programs\Python\Python38\lib\site-packages\django\db\models\base.py", line 739, in save
    self.save_base(using=using, force_insert=force_insert,
  File "C:\Users\young\AppData\Local\Programs\Python\Python38\lib\site-packages\django\db\models\base.py", line 776, in save_base
    updated = self._save_table(
  File "C:\Users\young\AppData\Local\Programs\Python\Python38\lib\site-packages\django\db\models\base.py", line 881, in _save_table
    results = self._do_insert(cls._base_manager, using, fields, returning_fields, raw)
  File "C:\Users\young\AppData\Local\Programs\Python\Python38\lib\site-packages\django\db\models\base.py", line 919, in _do_insert
    return manager._insert(
  File "C:\Users\young\AppData\Local\Programs\Python\Python38\lib\site-packages\django\db\models\manager.py", line 85, in manager_method
    return getattr(self.get_queryset(), name)(*args, **kwargs)
  File "C:\Users\young\AppData\Local\Programs\Python\Python38\lib\site-packages\django\db\models\query.py", line 1270, in _insert
    return query.get_compiler(using=using).execute_sql(returning_fields)
  File "C:\Users\young\AppData\Local\Programs\Python\Python38\lib\site-packages\django\db\models\sql\compiler.py", line 1416, in execute_sql
    cursor.execute(sql, params)
  File "C:\Users\young\AppData\Local\Programs\Python\Python38\lib\site-packages\django\db\backends\utils.py", line 98, in execute
    return super().execute(sql, params)
  File "C:\Users\young\AppData\Local\Programs\Python\Python38\lib\site-packages\django\db\backends\utils.py", line 66, in execute
    return self._execute_with_wrappers(sql, params, many=False, executor=self._execute)
  File "C:\Users\young\AppData\Local\Programs\Python\Python38\lib\site-packages\django\db\backends\utils.py", line 75, in _execute_with_wrappers
    return executor(sql, params, many, context)
  File "C:\Users\young\AppData\Local\Programs\Python\Python38\lib\site-packages\django\db\backends\utils.py", line 84, in _execute
    return self.cursor.execute(sql, params)
  File "C:\Users\young\AppData\Local\Programs\Python\Python38\lib\site-packages\django\db\utils.py", line 90, in __exit__
    raise dj_exc_value.with_traceback(traceback) from exc_value
  File "C:\Users\young\AppData\Local\Programs\Python\Python38\lib\site-packages\django\db\backends\utils.py", line 84, in _execute
    return self.cursor.execute(sql, params)
  File "C:\Users\young\AppData\Local\Programs\Python\Python38\lib\site-packages\django\db\backends\mysql\base.py", line 73, in execute
    return self.cursor.execute(query, args)
  File "C:\Users\young\AppData\Local\Programs\Python\Python38\lib\site-packages\pymysql\cursors.py", line 148, in execute
    result = self._query(query)
  File "C:\Users\young\AppData\Local\Programs\Python\Python38\lib\site-packages\pymysql\cursors.py", line 310, in _query
    conn.query(q)
  File "C:\Users\young\AppData\Local\Programs\Python\Python38\lib\site-packages\pymysql\connections.py", line 548, in query
    self._affected_rows = self._read_query_result(unbuffered=unbuffered)
  File "C:\Users\young\AppData\Local\Programs\Python\Python38\lib\site-packages\pymysql\connections.py", line 775, in _read_query_result
    result.read()
  File "C:\Users\young\AppData\Local\Programs\Python\Python38\lib\site-packages\pymysql\connections.py", line 1156, in read
    first_packet = self.connection._read_packet()
  File "C:\Users\young\AppData\Local\Programs\Python\Python38\lib\site-packages\pymysql\connections.py", line 725, in _read_packet
    packet.raise_for_error()
  File "C:\Users\young\AppData\Local\Programs\Python\Python38\lib\site-packages\pymysql\protocol.py", line 221, in raise_for_error
    err.raise_mysql_exception(self._data)
  File "C:\Users\young\AppData\Local\Programs\Python\Python38\lib\site-packages\pymysql\err.py", line 143, in raise_mysql_exception
    raise errorclass(errno, errval)
django.db.utils.DataError: (1406, "Data too long for column 'abbreviation' at row 1")
[2022-08-18 11:24:49,863] [basehttp.py:161] [basehttp:log_message] [ERROR]- "POST /polls/addpark/ HTTP/1.1" 500 332557
[2022-08-18 11:25:33,845] [basehttp.py:161] [basehttp:log_message] [INFO]- "GET /polls/addpark/ HTTP/1.1" 200 639
[2022-08-18 11:25:38,629] [log.py:224] [log:log_response] [ERROR]- Internal Server Error: /polls/addpark/
Traceback (most recent call last):
  File "C:\Users\young\AppData\Local\Programs\Python\Python38\lib\site-packages\django\db\backends\utils.py", line 84, in _execute
    return self.cursor.execute(sql, params)
  File "C:\Users\young\AppData\Local\Programs\Python\Python38\lib\site-packages\django\db\backends\mysql\base.py", line 73, in execute
    return self.cursor.execute(query, args)
  File "C:\Users\young\AppData\Local\Programs\Python\Python38\lib\site-packages\pymysql\cursors.py", line 148, in execute
    result = self._query(query)
  File "C:\Users\young\AppData\Local\Programs\Python\Python38\lib\site-packages\pymysql\cursors.py", line 310, in _query
    conn.query(q)
  File "C:\Users\young\AppData\Local\Programs\Python\Python38\lib\site-packages\pymysql\connections.py", line 548, in query
    self._affected_rows = self._read_query_result(unbuffered=unbuffered)
  File "C:\Users\young\AppData\Local\Programs\Python\Python38\lib\site-packages\pymysql\connections.py", line 775, in _read_query_result
    result.read()
  File "C:\Users\young\AppData\Local\Programs\Python\Python38\lib\site-packages\pymysql\connections.py", line 1156, in read
    first_packet = self.connection._read_packet()
  File "C:\Users\young\AppData\Local\Programs\Python\Python38\lib\site-packages\pymysql\connections.py", line 725, in _read_packet
    packet.raise_for_error()
  File "C:\Users\young\AppData\Local\Programs\Python\Python38\lib\site-packages\pymysql\protocol.py", line 221, in raise_for_error
    err.raise_mysql_exception(self._data)
  File "C:\Users\young\AppData\Local\Programs\Python\Python38\lib\site-packages\pymysql\err.py", line 143, in raise_mysql_exception
    raise errorclass(errno, errval)
pymysql.err.DataError: (1406, "Data too long for column 'abbreviation' at row 1")

The above exception was the direct cause of the following exception:

Traceback (most recent call last):
  File "C:\Users\young\AppData\Local\Programs\Python\Python38\lib\site-packages\django\core\handlers\exception.py", line 47, in inner
    response = get_response(request)
  File "C:\Users\young\AppData\Local\Programs\Python\Python38\lib\site-packages\django\core\handlers\base.py", line 181, in _get_response
    response = wrapped_callback(request, *callback_args, **callback_kwargs)
  File "E:\zl\git-django-qyzs\django_wx_qhzs\polls\views.py", line 140, in add_park
    Park.objects.create(naturalLevel=naturalLevel_v, ParkLevel=ParkLevel_v,
  File "C:\Users\young\AppData\Local\Programs\Python\Python38\lib\site-packages\django\db\models\manager.py", line 85, in manager_method
    return getattr(self.get_queryset(), name)(*args, **kwargs)
  File "C:\Users\young\AppData\Local\Programs\Python\Python38\lib\site-packages\django\db\models\query.py", line 453, in create
    obj.save(force_insert=True, using=self.db)
  File "C:\Users\young\AppData\Local\Programs\Python\Python38\lib\site-packages\django\db\models\base.py", line 739, in save
    self.save_base(using=using, force_insert=force_insert,
  File "C:\Users\young\AppData\Local\Programs\Python\Python38\lib\site-packages\django\db\models\base.py", line 776, in save_base
    updated = self._save_table(
  File "C:\Users\young\AppData\Local\Programs\Python\Python38\lib\site-packages\django\db\models\base.py", line 881, in _save_table
    results = self._do_insert(cls._base_manager, using, fields, returning_fields, raw)
  File "C:\Users\young\AppData\Local\Programs\Python\Python38\lib\site-packages\django\db\models\base.py", line 919, in _do_insert
    return manager._insert(
  File "C:\Users\young\AppData\Local\Programs\Python\Python38\lib\site-packages\django\db\models\manager.py", line 85, in manager_method
    return getattr(self.get_queryset(), name)(*args, **kwargs)
  File "C:\Users\young\AppData\Local\Programs\Python\Python38\lib\site-packages\django\db\models\query.py", line 1270, in _insert
    return query.get_compiler(using=using).execute_sql(returning_fields)
  File "C:\Users\young\AppData\Local\Programs\Python\Python38\lib\site-packages\django\db\models\sql\compiler.py", line 1416, in execute_sql
    cursor.execute(sql, params)
  File "C:\Users\young\AppData\Local\Programs\Python\Python38\lib\site-packages\django\db\backends\utils.py", line 98, in execute
    return super().execute(sql, params)
  File "C:\Users\young\AppData\Local\Programs\Python\Python38\lib\site-packages\django\db\backends\utils.py", line 66, in execute
    return self._execute_with_wrappers(sql, params, many=False, executor=self._execute)
  File "C:\Users\young\AppData\Local\Programs\Python\Python38\lib\site-packages\django\db\backends\utils.py", line 75, in _execute_with_wrappers
    return executor(sql, params, many, context)
  File "C:\Users\young\AppData\Local\Programs\Python\Python38\lib\site-packages\django\db\backends\utils.py", line 84, in _execute
    return self.cursor.execute(sql, params)
  File "C:\Users\young\AppData\Local\Programs\Python\Python38\lib\site-packages\django\db\utils.py", line 90, in __exit__
    raise dj_exc_value.with_traceback(traceback) from exc_value
  File "C:\Users\young\AppData\Local\Programs\Python\Python38\lib\site-packages\django\db\backends\utils.py", line 84, in _execute
    return self.cursor.execute(sql, params)
  File "C:\Users\young\AppData\Local\Programs\Python\Python38\lib\site-packages\django\db\backends\mysql\base.py", line 73, in execute
    return self.cursor.execute(query, args)
  File "C:\Users\young\AppData\Local\Programs\Python\Python38\lib\site-packages\pymysql\cursors.py", line 148, in execute
    result = self._query(query)
  File "C:\Users\young\AppData\Local\Programs\Python\Python38\lib\site-packages\pymysql\cursors.py", line 310, in _query
    conn.query(q)
  File "C:\Users\young\AppData\Local\Programs\Python\Python38\lib\site-packages\pymysql\connections.py", line 548, in query
    self._affected_rows = self._read_query_result(unbuffered=unbuffered)
  File "C:\Users\young\AppData\Local\Programs\Python\Python38\lib\site-packages\pymysql\connections.py", line 775, in _read_query_result
    result.read()
  File "C:\Users\young\AppData\Local\Programs\Python\Python38\lib\site-packages\pymysql\connections.py", line 1156, in read
    first_packet = self.connection._read_packet()
  File "C:\Users\young\AppData\Local\Programs\Python\Python38\lib\site-packages\pymysql\connections.py", line 725, in _read_packet
    packet.raise_for_error()
  File "C:\Users\young\AppData\Local\Programs\Python\Python38\lib\site-packages\pymysql\protocol.py", line 221, in raise_for_error
    err.raise_mysql_exception(self._data)
  File "C:\Users\young\AppData\Local\Programs\Python\Python38\lib\site-packages\pymysql\err.py", line 143, in raise_mysql_exception
    raise errorclass(errno, errval)
django.db.utils.DataError: (1406, "Data too long for column 'abbreviation' at row 1")
[2022-08-18 11:25:38,661] [basehttp.py:161] [basehttp:log_message] [ERROR]- "POST /polls/addpark/ HTTP/1.1" 500 288819
[2022-08-18 11:26:39,201] [autoreload.py:251] [autoreload:trigger_reload] [INFO]- E:\zl\git-django-qyzs\django_wx_qhzs\polls\models.py changed, reloading.
[2022-08-18 11:26:40,310] [autoreload.py:637] [autoreload:run_with_reloader] [INFO]- Watching for file changes with StatReloader
[2022-08-18 11:27:00,392] [autoreload.py:637] [autoreload:run_with_reloader] [INFO]- Watching for file changes with StatReloader
[2022-08-18 11:27:03,932] [basehttp.py:161] [basehttp:log_message] [INFO]- "GET /polls/addpark/ HTTP/1.1" 200 639
[2022-08-18 11:27:08,902] [log.py:224] [log:log_response] [ERROR]- Internal Server Error: /polls/addpark/
Traceback (most recent call last):
  File "C:\Users\young\AppData\Local\Programs\Python\Python38\lib\site-packages\django\db\backends\utils.py", line 84, in _execute
    return self.cursor.execute(sql, params)
  File "C:\Users\young\AppData\Local\Programs\Python\Python38\lib\site-packages\django\db\backends\mysql\base.py", line 73, in execute
    return self.cursor.execute(query, args)
  File "C:\Users\young\AppData\Local\Programs\Python\Python38\lib\site-packages\pymysql\cursors.py", line 148, in execute
    result = self._query(query)
  File "C:\Users\young\AppData\Local\Programs\Python\Python38\lib\site-packages\pymysql\cursors.py", line 310, in _query
    conn.query(q)
  File "C:\Users\young\AppData\Local\Programs\Python\Python38\lib\site-packages\pymysql\connections.py", line 548, in query
    self._affected_rows = self._read_query_result(unbuffered=unbuffered)
  File "C:\Users\young\AppData\Local\Programs\Python\Python38\lib\site-packages\pymysql\connections.py", line 775, in _read_query_result
    result.read()
  File "C:\Users\young\AppData\Local\Programs\Python\Python38\lib\site-packages\pymysql\connections.py", line 1156, in read
    first_packet = self.connection._read_packet()
  File "C:\Users\young\AppData\Local\Programs\Python\Python38\lib\site-packages\pymysql\connections.py", line 725, in _read_packet
    packet.raise_for_error()
  File "C:\Users\young\AppData\Local\Programs\Python\Python38\lib\site-packages\pymysql\protocol.py", line 221, in raise_for_error
    err.raise_mysql_exception(self._data)
  File "C:\Users\young\AppData\Local\Programs\Python\Python38\lib\site-packages\pymysql\err.py", line 143, in raise_mysql_exception
    raise errorclass(errno, errval)
pymysql.err.DataError: (1406, "Data too long for column 'abbreviation' at row 1")

The above exception was the direct cause of the following exception:

Traceback (most recent call last):
  File "C:\Users\young\AppData\Local\Programs\Python\Python38\lib\site-packages\django\core\handlers\exception.py", line 47, in inner
    response = get_response(request)
  File "C:\Users\young\AppData\Local\Programs\Python\Python38\lib\site-packages\django\core\handlers\base.py", line 181, in _get_response
    response = wrapped_callback(request, *callback_args, **callback_kwargs)
  File "E:\zl\git-django-qyzs\django_wx_qhzs\polls\views.py", line 140, in add_park
    Park.objects.create(naturalLevel=naturalLevel_v, ParkLevel=ParkLevel_v,
  File "C:\Users\young\AppData\Local\Programs\Python\Python38\lib\site-packages\django\db\models\manager.py", line 85, in manager_method
    return getattr(self.get_queryset(), name)(*args, **kwargs)
  File "C:\Users\young\AppData\Local\Programs\Python\Python38\lib\site-packages\django\db\models\query.py", line 453, in create
    obj.save(force_insert=True, using=self.db)
  File "C:\Users\young\AppData\Local\Programs\Python\Python38\lib\site-packages\django\db\models\base.py", line 739, in save
    self.save_base(using=using, force_insert=force_insert,
  File "C:\Users\young\AppData\Local\Programs\Python\Python38\lib\site-packages\django\db\models\base.py", line 776, in save_base
    updated = self._save_table(
  File "C:\Users\young\AppData\Local\Programs\Python\Python38\lib\site-packages\django\db\models\base.py", line 881, in _save_table
    results = self._do_insert(cls._base_manager, using, fields, returning_fields, raw)
  File "C:\Users\young\AppData\Local\Programs\Python\Python38\lib\site-packages\django\db\models\base.py", line 919, in _do_insert
    return manager._insert(
  File "C:\Users\young\AppData\Local\Programs\Python\Python38\lib\site-packages\django\db\models\manager.py", line 85, in manager_method
    return getattr(self.get_queryset(), name)(*args, **kwargs)
  File "C:\Users\young\AppData\Local\Programs\Python\Python38\lib\site-packages\django\db\models\query.py", line 1270, in _insert
    return query.get_compiler(using=using).execute_sql(returning_fields)
  File "C:\Users\young\AppData\Local\Programs\Python\Python38\lib\site-packages\django\db\models\sql\compiler.py", line 1416, in execute_sql
    cursor.execute(sql, params)
  File "C:\Users\young\AppData\Local\Programs\Python\Python38\lib\site-packages\django\db\backends\utils.py", line 98, in execute
    return super().execute(sql, params)
  File "C:\Users\young\AppData\Local\Programs\Python\Python38\lib\site-packages\django\db\backends\utils.py", line 66, in execute
    return self._execute_with_wrappers(sql, params, many=False, executor=self._execute)
  File "C:\Users\young\AppData\Local\Programs\Python\Python38\lib\site-packages\django\db\backends\utils.py", line 75, in _execute_with_wrappers
    return executor(sql, params, many, context)
  File "C:\Users\young\AppData\Local\Programs\Python\Python38\lib\site-packages\django\db\backends\utils.py", line 84, in _execute
    return self.cursor.execute(sql, params)
  File "C:\Users\young\AppData\Local\Programs\Python\Python38\lib\site-packages\django\db\utils.py", line 90, in __exit__
    raise dj_exc_value.with_traceback(traceback) from exc_value
  File "C:\Users\young\AppData\Local\Programs\Python\Python38\lib\site-packages\django\db\backends\utils.py", line 84, in _execute
    return self.cursor.execute(sql, params)
  File "C:\Users\young\AppData\Local\Programs\Python\Python38\lib\site-packages\django\db\backends\mysql\base.py", line 73, in execute
    return self.cursor.execute(query, args)
  File "C:\Users\young\AppData\Local\Programs\Python\Python38\lib\site-packages\pymysql\cursors.py", line 148, in execute
    result = self._query(query)
  File "C:\Users\young\AppData\Local\Programs\Python\Python38\lib\site-packages\pymysql\cursors.py", line 310, in _query
    conn.query(q)
  File "C:\Users\young\AppData\Local\Programs\Python\Python38\lib\site-packages\pymysql\connections.py", line 548, in query
    self._affected_rows = self._read_query_result(unbuffered=unbuffered)
  File "C:\Users\young\AppData\Local\Programs\Python\Python38\lib\site-packages\pymysql\connections.py", line 775, in _read_query_result
    result.read()
  File "C:\Users\young\AppData\Local\Programs\Python\Python38\lib\site-packages\pymysql\connections.py", line 1156, in read
    first_packet = self.connection._read_packet()
  File "C:\Users\young\AppData\Local\Programs\Python\Python38\lib\site-packages\pymysql\connections.py", line 725, in _read_packet
    packet.raise_for_error()
  File "C:\Users\young\AppData\Local\Programs\Python\Python38\lib\site-packages\pymysql\protocol.py", line 221, in raise_for_error
    err.raise_mysql_exception(self._data)
  File "C:\Users\young\AppData\Local\Programs\Python\Python38\lib\site-packages\pymysql\err.py", line 143, in raise_mysql_exception
    raise errorclass(errno, errval)
django.db.utils.DataError: (1406, "Data too long for column 'abbreviation' at row 1")
[2022-08-18 11:27:08,919] [basehttp.py:161] [basehttp:log_message] [ERROR]- "POST /polls/addpark/ HTTP/1.1" 500 332557
[2022-08-18 11:28:50,537] [autoreload.py:637] [autoreload:run_with_reloader] [INFO]- Watching for file changes with StatReloader
[2022-08-18 11:29:02,657] [basehttp.py:161] [basehttp:log_message] [INFO]- "GET /polls/addpark/ HTTP/1.1" 200 639
[2022-08-18 11:29:06,801] [log.py:224] [log:log_response] [ERROR]- Internal Server Error: /polls/addpark/
Traceback (most recent call last):
  File "C:\Users\young\AppData\Local\Programs\Python\Python38\lib\site-packages\django\db\backends\utils.py", line 84, in _execute
    return self.cursor.execute(sql, params)
  File "C:\Users\young\AppData\Local\Programs\Python\Python38\lib\site-packages\django\db\backends\mysql\base.py", line 73, in execute
    return self.cursor.execute(query, args)
  File "C:\Users\young\AppData\Local\Programs\Python\Python38\lib\site-packages\pymysql\cursors.py", line 148, in execute
    result = self._query(query)
  File "C:\Users\young\AppData\Local\Programs\Python\Python38\lib\site-packages\pymysql\cursors.py", line 310, in _query
    conn.query(q)
  File "C:\Users\young\AppData\Local\Programs\Python\Python38\lib\site-packages\pymysql\connections.py", line 548, in query
    self._affected_rows = self._read_query_result(unbuffered=unbuffered)
  File "C:\Users\young\AppData\Local\Programs\Python\Python38\lib\site-packages\pymysql\connections.py", line 775, in _read_query_result
    result.read()
  File "C:\Users\young\AppData\Local\Programs\Python\Python38\lib\site-packages\pymysql\connections.py", line 1156, in read
    first_packet = self.connection._read_packet()
  File "C:\Users\young\AppData\Local\Programs\Python\Python38\lib\site-packages\pymysql\connections.py", line 725, in _read_packet
    packet.raise_for_error()
  File "C:\Users\young\AppData\Local\Programs\Python\Python38\lib\site-packages\pymysql\protocol.py", line 221, in raise_for_error
    err.raise_mysql_exception(self._data)
  File "C:\Users\young\AppData\Local\Programs\Python\Python38\lib\site-packages\pymysql\err.py", line 143, in raise_mysql_exception
    raise errorclass(errno, errval)
pymysql.err.ProgrammingError: (1146, "Table 'django_demo.sd_park' doesn't exist")

The above exception was the direct cause of the following exception:

Traceback (most recent call last):
  File "C:\Users\young\AppData\Local\Programs\Python\Python38\lib\site-packages\django\core\handlers\exception.py", line 47, in inner
    response = get_response(request)
  File "C:\Users\young\AppData\Local\Programs\Python\Python38\lib\site-packages\django\core\handlers\base.py", line 181, in _get_response
    response = wrapped_callback(request, *callback_args, **callback_kwargs)
  File "E:\zl\git-django-qyzs\django_wx_qhzs\polls\views.py", line 138, in add_park
    exists = Park.objects.filter(name1=name1_v).exists()
  File "C:\Users\young\AppData\Local\Programs\Python\Python38\lib\site-packages\django\db\models\query.py", line 808, in exists
    return self.query.has_results(using=self.db)
  File "C:\Users\young\AppData\Local\Programs\Python\Python38\lib\site-packages\django\db\models\sql\query.py", line 561, in has_results
    return compiler.has_results()
  File "C:\Users\young\AppData\Local\Programs\Python\Python38\lib\site-packages\django\db\models\sql\compiler.py", line 1145, in has_results
    return bool(self.execute_sql(SINGLE))
  File "C:\Users\young\AppData\Local\Programs\Python\Python38\lib\site-packages\django\db\models\sql\compiler.py", line 1175, in execute_sql
    cursor.execute(sql, params)
  File "C:\Users\young\AppData\Local\Programs\Python\Python38\lib\site-packages\django\db\backends\utils.py", line 98, in execute
    return super().execute(sql, params)
  File "C:\Users\young\AppData\Local\Programs\Python\Python38\lib\site-packages\django\db\backends\utils.py", line 66, in execute
    return self._execute_with_wrappers(sql, params, many=False, executor=self._execute)
  File "C:\Users\young\AppData\Local\Programs\Python\Python38\lib\site-packages\django\db\backends\utils.py", line 75, in _execute_with_wrappers
    return executor(sql, params, many, context)
  File "C:\Users\young\AppData\Local\Programs\Python\Python38\lib\site-packages\django\db\backends\utils.py", line 84, in _execute
    return self.cursor.execute(sql, params)
  File "C:\Users\young\AppData\Local\Programs\Python\Python38\lib\site-packages\django\db\utils.py", line 90, in __exit__
    raise dj_exc_value.with_traceback(traceback) from exc_value
  File "C:\Users\young\AppData\Local\Programs\Python\Python38\lib\site-packages\django\db\backends\utils.py", line 84, in _execute
    return self.cursor.execute(sql, params)
  File "C:\Users\young\AppData\Local\Programs\Python\Python38\lib\site-packages\django\db\backends\mysql\base.py", line 73, in execute
    return self.cursor.execute(query, args)
  File "C:\Users\young\AppData\Local\Programs\Python\Python38\lib\site-packages\pymysql\cursors.py", line 148, in execute
    result = self._query(query)
  File "C:\Users\young\AppData\Local\Programs\Python\Python38\lib\site-packages\pymysql\cursors.py", line 310, in _query
    conn.query(q)
  File "C:\Users\young\AppData\Local\Programs\Python\Python38\lib\site-packages\pymysql\connections.py", line 548, in query
    self._affected_rows = self._read_query_result(unbuffered=unbuffered)
  File "C:\Users\young\AppData\Local\Programs\Python\Python38\lib\site-packages\pymysql\connections.py", line 775, in _read_query_result
    result.read()
  File "C:\Users\young\AppData\Local\Programs\Python\Python38\lib\site-packages\pymysql\connections.py", line 1156, in read
    first_packet = self.connection._read_packet()
  File "C:\Users\young\AppData\Local\Programs\Python\Python38\lib\site-packages\pymysql\connections.py", line 725, in _read_packet
    packet.raise_for_error()
  File "C:\Users\young\AppData\Local\Programs\Python\Python38\lib\site-packages\pymysql\protocol.py", line 221, in raise_for_error
    err.raise_mysql_exception(self._data)
  File "C:\Users\young\AppData\Local\Programs\Python\Python38\lib\site-packages\pymysql\err.py", line 143, in raise_mysql_exception
    raise errorclass(errno, errval)
django.db.utils.ProgrammingError: (1146, "Table 'django_demo.sd_park' doesn't exist")
[2022-08-18 11:29:06,813] [basehttp.py:161] [basehttp:log_message] [ERROR]- "POST /polls/addpark/ HTTP/1.1" 500 206040
[2022-08-18 11:42:05,957] [autoreload.py:637] [autoreload:run_with_reloader] [INFO]- Watching for file changes with StatReloader
[2022-08-18 11:42:11,592] [basehttp.py:161] [basehttp:log_message] [INFO]- "GET /polls/addpark/ HTTP/1.1" 200 639
[2022-08-18 11:42:18,405] [basehttp.py:161] [basehttp:log_message] [INFO]- "POST /polls/addpark/ HTTP/1.1" 200 639
[2022-08-18 13:10:53,084] [autoreload.py:637] [autoreload:run_with_reloader] [INFO]- Watching for file changes with StatReloader
[2022-08-18 13:12:45,271] [autoreload.py:637] [autoreload:run_with_reloader] [INFO]- Watching for file changes with StatReloader
[2022-08-18 13:12:49,658] [basehttp.py:161] [basehttp:log_message] [INFO]- "GET / HTTP/1.1" 200 6021
[2022-08-18 13:12:49,697] [basehttp.py:161] [basehttp:log_message] [INFO]- "GET /static/rest_framework/css/bootstrap-tweaks.css HTTP/1.1" 200 3385
[2022-08-18 13:12:49,701] [basehttp.py:161] [basehttp:log_message] [INFO]- "GET /static/rest_framework/css/prettify.css HTTP/1.1" 200 817
[2022-08-18 13:12:49,702] [basehttp.py:161] [basehttp:log_message] [INFO]- "GET /static/rest_framework/css/default.css HTTP/1.1" 200 1152
[2022-08-18 13:12:49,715] [basehttp.py:161] [basehttp:log_message] [INFO]- "GET /static/rest_framework/js/csrf.js HTTP/1.1" 200 1719
[2022-08-18 13:12:49,716] [basehttp.py:161] [basehttp:log_message] [INFO]- "GET /static/rest_framework/css/bootstrap.min.css HTTP/1.1" 200 121457
[2022-08-18 13:12:49,717] [basehttp.py:161] [basehttp:log_message] [INFO]- "GET /static/rest_framework/js/ajax-form.js HTTP/1.1" 200 3597
[2022-08-18 13:12:49,722] [basehttp.py:161] [basehttp:log_message] [INFO]- "GET /static/rest_framework/js/default.js HTTP/1.1" 200 1268
[2022-08-18 13:12:49,723] [basehttp.py:161] [basehttp:log_message] [INFO]- "GET /static/rest_framework/js/jquery-3.5.1.min.js HTTP/1.1" 200 89476
[2022-08-18 13:12:49,724] [basehttp.py:161] [basehttp:log_message] [INFO]- "GET /static/rest_framework/js/bootstrap.min.js HTTP/1.1" 200 39680
[2022-08-18 13:12:49,725] [basehttp.py:161] [basehttp:log_message] [INFO]- "GET /static/rest_framework/js/prettify-min.js HTTP/1.1" 200 13632
[2022-08-18 13:12:49,738] [basehttp.py:161] [basehttp:log_message] [INFO]- "GET /static/rest_framework/img/grid.png HTTP/1.1" 200 1458
[2022-08-18 13:12:49,911] [log.py:224] [log:log_response] [WARNING]- Not Found: /favicon.ico
[2022-08-18 13:12:49,912] [basehttp.py:161] [basehttp:log_message] [WARNING]- "GET /favicon.ico HTTP/1.1" 404 9344
[2022-08-18 13:12:58,202] [basehttp.py:161] [basehttp:log_message] [INFO]- "GET /addpark/ HTTP/1.1" 200 639
[2022-08-18 13:12:58,234] [basehttp.py:161] [basehttp:log_message] [WARNING]- "GET /static/css/bootstrap.min.css HTTP/1.1" 404 1822
[2022-08-18 13:12:58,235] [basehttp.py:161] [basehttp:log_message] [WARNING]- "GET /static/js/bootstrap.min.js HTTP/1.1" 404 1816
[2022-08-18 13:12:58,235] [basehttp.py:161] [basehttp:log_message] [WARNING]- "GET /static/js/jquery-3.6.0.min.js HTTP/1.1" 404 1825
[2022-08-18 13:39:01,643] [autoreload.py:251] [autoreload:trigger_reload] [INFO]- E:\zl\git-django-qyzs\django_wx_qhzs\wxcloudrun\settings.py changed, reloading.
[2022-08-18 13:39:03,080] [autoreload.py:637] [autoreload:run_with_reloader] [INFO]- Watching for file changes with StatReloader
[2022-08-18 13:39:08,195] [autoreload.py:251] [autoreload:trigger_reload] [INFO]- E:\zl\git-django-qyzs\django_wx_qhzs\wxcloudrun\settings.py changed, reloading.
[2022-08-18 13:39:09,276] [autoreload.py:637] [autoreload:run_with_reloader] [INFO]- Watching for file changes with StatReloader
[2022-08-18 15:06:53,012] [autoreload.py:251] [autoreload:trigger_reload] [INFO]- E:\zl\git-django-qyzs\django_wx_qhzs\polls\views.py changed, reloading.
[2022-08-18 15:06:53,915] [autoreload.py:637] [autoreload:run_with_reloader] [INFO]- Watching for file changes with StatReloader
[2022-08-19 10:45:19,038] [autoreload.py:251] [autoreload:trigger_reload] [INFO]- E:\zl\git-django-qyzs\django_wx_qhzs\polls\models.py changed, reloading.
