[2022-08-12 14:30:50,966] [autoreload.py:637] [autoreload:run_with_reloader] [INFO]- Watching for file changes with StatReloader
[2022-08-12 14:32:07,195] [autoreload.py:637] [autoreload:run_with_reloader] [INFO]- Watching for file changes with StatReloader
[2022-08-12 14:33:47,021] [autoreload.py:637] [autoreload:run_with_reloader] [INFO]- Watching for file changes with StatReloader
[2022-08-12 14:33:55,249] [basehttp.py:161] [basehttp:log_message] [INFO]- "GET / HTTP/1.1" 200 10137
[2022-08-12 14:33:55,694] [views.py:40] [views:counter] [INFO]- response result: {"code": 0, "data": 0}
[2022-08-12 14:33:55,696] [basehttp.py:161] [basehttp:log_message] [INFO]- "GET /api/count HTTP/1.1" 200 22
[2022-08-12 14:34:01,023] [basehttp.py:161] [basehttp:log_message] [INFO]- "GET /polls/ HTTP/1.1" 200 6141
[2022-08-12 14:34:01,275] [log.py:224] [log:log_response] [WARNING]- Not Found: /favicon.ico
[2022-08-12 14:34:01,277] [basehttp.py:161] [basehttp:log_message] [WARNING]- "GET /favicon.ico HTTP/1.1" 404 2451
[2022-08-12 14:35:59,204] [log.py:224] [log:log_response] [WARNING]- Not Found: /polls/apppark
[2022-08-12 14:35:59,212] [basehttp.py:161] [basehttp:log_message] [WARNING]- "GET /polls/apppark HTTP/1.1" 404 9672
[2022-08-12 14:36:07,553] [basehttp.py:161] [basehttp:log_message] [INFO]- "GET /polls/addpark HTTP/1.1" 301 0
[2022-08-12 14:36:07,560] [basehttp.py:161] [basehttp:log_message] [INFO]- "GET /polls/addpark/ HTTP/1.1" 200 639
[2022-08-12 14:36:14,267] [basehttp.py:161] [basehttp:log_message] [INFO]- "POST /polls/addpark/ HTTP/1.1" 200 639
[2022-08-12 14:36:58,282] [autoreload.py:637] [autoreload:run_with_reloader] [INFO]- Watching for file changes with StatReloader
[2022-08-12 14:37:04,338] [basehttp.py:161] [basehttp:log_message] [INFO]- "GET /polls/addpark/ HTTP/1.1" 200 639
[2022-08-12 14:37:10,383] [log.py:224] [log:log_response] [ERROR]- Internal Server Error: /polls/addpark/
Traceback (most recent call last):
  File "C:\Users\young\AppData\Local\Programs\Python\Python38\lib\site-packages\django\db\backends\utils.py", line 84, in _execute
    return self.cursor.execute(sql, params)
  File "C:\Users\young\AppData\Local\Programs\Python\Python38\lib\site-packages\django\db\backends\mysql\base.py", line 73, in execute
    return self.cursor.execute(query, args)
  File "C:\Users\young\AppData\Local\Programs\Python\Python38\lib\site-packages\pymysql\cursors.py", line 148, in execute
    result = self._query(query)
  File "C:\Users\young\AppData\Local\Programs\Python\Python38\lib\site-packages\pymysql\cursors.py", line 310, in _query
    conn.query(q)
  File "C:\Users\young\AppData\Local\Programs\Python\Python38\lib\site-packages\pymysql\connections.py", line 548, in query
    self._affected_rows = self._read_query_result(unbuffered=unbuffered)
  File "C:\Users\young\AppData\Local\Programs\Python\Python38\lib\site-packages\pymysql\connections.py", line 775, in _read_query_result
    result.read()
  File "C:\Users\young\AppData\Local\Programs\Python\Python38\lib\site-packages\pymysql\connections.py", line 1156, in read
    first_packet = self.connection._read_packet()
  File "C:\Users\young\AppData\Local\Programs\Python\Python38\lib\site-packages\pymysql\connections.py", line 725, in _read_packet
    packet.raise_for_error()
  File "C:\Users\young\AppData\Local\Programs\Python\Python38\lib\site-packages\pymysql\protocol.py", line 221, in raise_for_error
    err.raise_mysql_exception(self._data)
  File "C:\Users\young\AppData\Local\Programs\Python\Python38\lib\site-packages\pymysql\err.py", line 143, in raise_mysql_exception
    raise errorclass(errno, errval)
pymysql.err.DataError: (1406, "Data too long for column 'abbreviation' at row 1")

The above exception was the direct cause of the following exception:

Traceback (most recent call last):
  File "C:\Users\young\AppData\Local\Programs\Python\Python38\lib\site-packages\django\core\handlers\exception.py", line 47, in inner
    response = get_response(request)
  File "C:\Users\young\AppData\Local\Programs\Python\Python38\lib\site-packages\django\core\handlers\base.py", line 181, in _get_response
    response = wrapped_callback(request, *callback_args, **callback_kwargs)
  File "E:\zl\git-django-qyzs\django_wx_qhzs\polls\views.py", line 140, in add_park
    Park.objects.create(naturalLevel=naturalLevel_v, ParkLevel=ParkLevel_v,
  File "C:\Users\young\AppData\Local\Programs\Python\Python38\lib\site-packages\django\db\models\manager.py", line 85, in manager_method
    return getattr(self.get_queryset(), name)(*args, **kwargs)
  File "C:\Users\young\AppData\Local\Programs\Python\Python38\lib\site-packages\django\db\models\query.py", line 453, in create
    obj.save(force_insert=True, using=self.db)
  File "C:\Users\young\AppData\Local\Programs\Python\Python38\lib\site-packages\django\db\models\base.py", line 739, in save
    self.save_base(using=using, force_insert=force_insert,
  File "C:\Users\young\AppData\Local\Programs\Python\Python38\lib\site-packages\django\db\models\base.py", line 776, in save_base
    updated = self._save_table(
  File "C:\Users\young\AppData\Local\Programs\Python\Python38\lib\site-packages\django\db\models\base.py", line 881, in _save_table
    results = self._do_insert(cls._base_manager, using, fields, returning_fields, raw)
  File "C:\Users\young\AppData\Local\Programs\Python\Python38\lib\site-packages\django\db\models\base.py", line 919, in _do_insert
    return manager._insert(
  File "C:\Users\young\AppData\Local\Programs\Python\Python38\lib\site-packages\django\db\models\manager.py", line 85, in manager_method
    return getattr(self.get_queryset(), name)(*args, **kwargs)
  File "C:\Users\young\AppData\Local\Programs\Python\Python38\lib\site-packages\django\db\models\query.py", line 1270, in _insert
    return query.get_compiler(using=using).execute_sql(returning_fields)
  File "C:\Users\young\AppData\Local\Programs\Python\Python38\lib\site-packages\django\db\models\sql\compiler.py", line 1416, in execute_sql
    cursor.execute(sql, params)
  File "C:\Users\young\AppData\Local\Programs\Python\Python38\lib\site-packages\django\db\backends\utils.py", line 98, in execute
    return super().execute(sql, params)
  File "C:\Users\young\AppData\Local\Programs\Python\Python38\lib\site-packages\django\db\backends\utils.py", line 66, in execute
    return self._execute_with_wrappers(sql, params, many=False, executor=self._execute)
  File "C:\Users\young\AppData\Local\Programs\Python\Python38\lib\site-packages\django\db\backends\utils.py", line 75, in _execute_with_wrappers
    return executor(sql, params, many, context)
  File "C:\Users\young\AppData\Local\Programs\Python\Python38\lib\site-packages\django\db\backends\utils.py", line 84, in _execute
    return self.cursor.execute(sql, params)
  File "C:\Users\young\AppData\Local\Programs\Python\Python38\lib\site-packages\django\db\utils.py", line 90, in __exit__
    raise dj_exc_value.with_traceback(traceback) from exc_value
  File "C:\Users\young\AppData\Local\Programs\Python\Python38\lib\site-packages\django\db\backends\utils.py", line 84, in _execute
    return self.cursor.execute(sql, params)
  File "C:\Users\young\AppData\Local\Programs\Python\Python38\lib\site-packages\django\db\backends\mysql\base.py", line 73, in execute
    return self.cursor.execute(query, args)
  File "C:\Users\young\AppData\Local\Programs\Python\Python38\lib\site-packages\pymysql\cursors.py", line 148, in execute
    result = self._query(query)
  File "C:\Users\young\AppData\Local\Programs\Python\Python38\lib\site-packages\pymysql\cursors.py", line 310, in _query
    conn.query(q)
  File "C:\Users\young\AppData\Local\Programs\Python\Python38\lib\site-packages\pymysql\connections.py", line 548, in query
    self._affected_rows = self._read_query_result(unbuffered=unbuffered)
  File "C:\Users\young\AppData\Local\Programs\Python\Python38\lib\site-packages\pymysql\connections.py", line 775, in _read_query_result
    result.read()
  File "C:\Users\young\AppData\Local\Programs\Python\Python38\lib\site-packages\pymysql\connections.py", line 1156, in read
    first_packet = self.connection._read_packet()
  File "C:\Users\young\AppData\Local\Programs\Python\Python38\lib\site-packages\pymysql\connections.py", line 725, in _read_packet
    packet.raise_for_error()
  File "C:\Users\young\AppData\Local\Programs\Python\Python38\lib\site-packages\pymysql\protocol.py", line 221, in raise_for_error
    err.raise_mysql_exception(self._data)
  File "C:\Users\young\AppData\Local\Programs\Python\Python38\lib\site-packages\pymysql\err.py", line 143, in raise_mysql_exception
    raise errorclass(errno, errval)
django.db.utils.DataError: (1406, "Data too long for column 'abbreviation' at row 1")
[2022-08-12 14:37:10,397] [basehttp.py:161] [basehttp:log_message] [ERROR]- "POST /polls/addpark/ HTTP/1.1" 500 260149
[2022-08-12 14:42:36,508] [autoreload.py:251] [autoreload:trigger_reload] [INFO]- E:\zl\git-django-qyzs\django_wx_qhzs\wxcloudrun\settings.py changed, reloading.
[2022-08-12 14:43:31,539] [autoreload.py:637] [autoreload:run_with_reloader] [INFO]- Watching for file changes with StatReloader
[2022-08-12 14:45:33,354] [autoreload.py:251] [autoreload:trigger_reload] [INFO]- E:\zl\git-django-qyzs\django_wx_qhzs\polls\views.py changed, reloading.
[2022-08-12 14:45:34,427] [autoreload.py:637] [autoreload:run_with_reloader] [INFO]- Watching for file changes with StatReloader
[2022-08-12 14:45:42,726] [basehttp.py:161] [basehttp:log_message] [INFO]- "GET /polls/addpark/ HTTP/1.1" 200 639
[2022-08-12 14:45:46,875] [log.py:224] [log:log_response] [ERROR]- Internal Server Error: /polls/addpark/
Traceback (most recent call last):
  File "C:\Users\young\AppData\Local\Programs\Python\Python38\lib\site-packages\django\db\backends\utils.py", line 84, in _execute
    return self.cursor.execute(sql, params)
  File "C:\Users\young\AppData\Local\Programs\Python\Python38\lib\site-packages\django\db\backends\mysql\base.py", line 73, in execute
    return self.cursor.execute(query, args)
  File "C:\Users\young\AppData\Local\Programs\Python\Python38\lib\site-packages\pymysql\cursors.py", line 148, in execute
    result = self._query(query)
  File "C:\Users\young\AppData\Local\Programs\Python\Python38\lib\site-packages\pymysql\cursors.py", line 310, in _query
    conn.query(q)
  File "C:\Users\young\AppData\Local\Programs\Python\Python38\lib\site-packages\pymysql\connections.py", line 548, in query
    self._affected_rows = self._read_query_result(unbuffered=unbuffered)
  File "C:\Users\young\AppData\Local\Programs\Python\Python38\lib\site-packages\pymysql\connections.py", line 775, in _read_query_result
    result.read()
  File "C:\Users\young\AppData\Local\Programs\Python\Python38\lib\site-packages\pymysql\connections.py", line 1156, in read
    first_packet = self.connection._read_packet()
  File "C:\Users\young\AppData\Local\Programs\Python\Python38\lib\site-packages\pymysql\connections.py", line 725, in _read_packet
    packet.raise_for_error()
  File "C:\Users\young\AppData\Local\Programs\Python\Python38\lib\site-packages\pymysql\protocol.py", line 221, in raise_for_error
    err.raise_mysql_exception(self._data)
  File "C:\Users\young\AppData\Local\Programs\Python\Python38\lib\site-packages\pymysql\err.py", line 143, in raise_mysql_exception
    raise errorclass(errno, errval)
pymysql.err.DataError: (1406, "Data too long for column 'abbreviation' at row 1")

The above exception was the direct cause of the following exception:

Traceback (most recent call last):
  File "C:\Users\young\AppData\Local\Programs\Python\Python38\lib\site-packages\django\core\handlers\exception.py", line 47, in inner
    response = get_response(request)
  File "C:\Users\young\AppData\Local\Programs\Python\Python38\lib\site-packages\django\core\handlers\base.py", line 181, in _get_response
    response = wrapped_callback(request, *callback_args, **callback_kwargs)
  File "E:\zl\git-django-qyzs\django_wx_qhzs\polls\views.py", line 140, in add_park
    Park.objects.create(naturalLevel=naturalLevel_v, ParkLevel=ParkLevel_v,
  File "C:\Users\young\AppData\Local\Programs\Python\Python38\lib\site-packages\django\db\models\manager.py", line 85, in manager_method
    return getattr(self.get_queryset(), name)(*args, **kwargs)
  File "C:\Users\young\AppData\Local\Programs\Python\Python38\lib\site-packages\django\db\models\query.py", line 453, in create
    obj.save(force_insert=True, using=self.db)
  File "C:\Users\young\AppData\Local\Programs\Python\Python38\lib\site-packages\django\db\models\base.py", line 739, in save
    self.save_base(using=using, force_insert=force_insert,
  File "C:\Users\young\AppData\Local\Programs\Python\Python38\lib\site-packages\django\db\models\base.py", line 776, in save_base
    updated = self._save_table(
  File "C:\Users\young\AppData\Local\Programs\Python\Python38\lib\site-packages\django\db\models\base.py", line 881, in _save_table
    results = self._do_insert(cls._base_manager, using, fields, returning_fields, raw)
  File "C:\Users\young\AppData\Local\Programs\Python\Python38\lib\site-packages\django\db\models\base.py", line 919, in _do_insert
    return manager._insert(
  File "C:\Users\young\AppData\Local\Programs\Python\Python38\lib\site-packages\django\db\models\manager.py", line 85, in manager_method
    return getattr(self.get_queryset(), name)(*args, **kwargs)
  File "C:\Users\young\AppData\Local\Programs\Python\Python38\lib\site-packages\django\db\models\query.py", line 1270, in _insert
    return query.get_compiler(using=using).execute_sql(returning_fields)
  File "C:\Users\young\AppData\Local\Programs\Python\Python38\lib\site-packages\django\db\models\sql\compiler.py", line 1416, in execute_sql
    cursor.execute(sql, params)
  File "C:\Users\young\AppData\Local\Programs\Python\Python38\lib\site-packages\django\db\backends\utils.py", line 98, in execute
    return super().execute(sql, params)
  File "C:\Users\young\AppData\Local\Programs\Python\Python38\lib\site-packages\django\db\backends\utils.py", line 66, in execute
    return self._execute_with_wrappers(sql, params, many=False, executor=self._execute)
  File "C:\Users\young\AppData\Local\Programs\Python\Python38\lib\site-packages\django\db\backends\utils.py", line 75, in _execute_with_wrappers
    return executor(sql, params, many, context)
  File "C:\Users\young\AppData\Local\Programs\Python\Python38\lib\site-packages\django\db\backends\utils.py", line 84, in _execute
    return self.cursor.execute(sql, params)
  File "C:\Users\young\AppData\Local\Programs\Python\Python38\lib\site-packages\django\db\utils.py", line 90, in __exit__
    raise dj_exc_value.with_traceback(traceback) from exc_value
  File "C:\Users\young\AppData\Local\Programs\Python\Python38\lib\site-packages\django\db\backends\utils.py", line 84, in _execute
    return self.cursor.execute(sql, params)
  File "C:\Users\young\AppData\Local\Programs\Python\Python38\lib\site-packages\django\db\backends\mysql\base.py", line 73, in execute
    return self.cursor.execute(query, args)
  File "C:\Users\young\AppData\Local\Programs\Python\Python38\lib\site-packages\pymysql\cursors.py", line 148, in execute
    result = self._query(query)
  File "C:\Users\young\AppData\Local\Programs\Python\Python38\lib\site-packages\pymysql\cursors.py", line 310, in _query
    conn.query(q)
  File "C:\Users\young\AppData\Local\Programs\Python\Python38\lib\site-packages\pymysql\connections.py", line 548, in query
    self._affected_rows = self._read_query_result(unbuffered=unbuffered)
  File "C:\Users\young\AppData\Local\Programs\Python\Python38\lib\site-packages\pymysql\connections.py", line 775, in _read_query_result
    result.read()
  File "C:\Users\young\AppData\Local\Programs\Python\Python38\lib\site-packages\pymysql\connections.py", line 1156, in read
    first_packet = self.connection._read_packet()
  File "C:\Users\young\AppData\Local\Programs\Python\Python38\lib\site-packages\pymysql\connections.py", line 725, in _read_packet
    packet.raise_for_error()
  File "C:\Users\young\AppData\Local\Programs\Python\Python38\lib\site-packages\pymysql\protocol.py", line 221, in raise_for_error
    err.raise_mysql_exception(self._data)
  File "C:\Users\young\AppData\Local\Programs\Python\Python38\lib\site-packages\pymysql\err.py", line 143, in raise_mysql_exception
    raise errorclass(errno, errval)
django.db.utils.DataError: (1406, "Data too long for column 'abbreviation' at row 1")
[2022-08-12 14:45:46,890] [basehttp.py:161] [basehttp:log_message] [ERROR]- "POST /polls/addpark/ HTTP/1.1" 500 260149
[2022-08-12 14:46:44,479] [autoreload.py:251] [autoreload:trigger_reload] [INFO]- E:\zl\git-django-qyzs\django_wx_qhzs\polls\models.py changed, reloading.
[2022-08-12 14:46:45,634] [autoreload.py:637] [autoreload:run_with_reloader] [INFO]- Watching for file changes with StatReloader
[2022-08-12 14:47:33,040] [autoreload.py:637] [autoreload:run_with_reloader] [INFO]- Watching for file changes with StatReloader
[2022-08-12 14:47:38,683] [basehttp.py:161] [basehttp:log_message] [INFO]- "GET /polls/addpark/ HTTP/1.1" 200 639
[2022-08-12 14:47:43,174] [log.py:224] [log:log_response] [ERROR]- Internal Server Error: /polls/addpark/
Traceback (most recent call last):
  File "C:\Users\young\AppData\Local\Programs\Python\Python38\lib\site-packages\django\db\backends\utils.py", line 84, in _execute
    return self.cursor.execute(sql, params)
  File "C:\Users\young\AppData\Local\Programs\Python\Python38\lib\site-packages\django\db\backends\mysql\base.py", line 73, in execute
    return self.cursor.execute(query, args)
  File "C:\Users\young\AppData\Local\Programs\Python\Python38\lib\site-packages\pymysql\cursors.py", line 148, in execute
    result = self._query(query)
  File "C:\Users\young\AppData\Local\Programs\Python\Python38\lib\site-packages\pymysql\cursors.py", line 310, in _query
    conn.query(q)
  File "C:\Users\young\AppData\Local\Programs\Python\Python38\lib\site-packages\pymysql\connections.py", line 548, in query
    self._affected_rows = self._read_query_result(unbuffered=unbuffered)
  File "C:\Users\young\AppData\Local\Programs\Python\Python38\lib\site-packages\pymysql\connections.py", line 775, in _read_query_result
    result.read()
  File "C:\Users\young\AppData\Local\Programs\Python\Python38\lib\site-packages\pymysql\connections.py", line 1156, in read
    first_packet = self.connection._read_packet()
  File "C:\Users\young\AppData\Local\Programs\Python\Python38\lib\site-packages\pymysql\connections.py", line 725, in _read_packet
    packet.raise_for_error()
  File "C:\Users\young\AppData\Local\Programs\Python\Python38\lib\site-packages\pymysql\protocol.py", line 221, in raise_for_error
    err.raise_mysql_exception(self._data)
  File "C:\Users\young\AppData\Local\Programs\Python\Python38\lib\site-packages\pymysql\err.py", line 143, in raise_mysql_exception
    raise errorclass(errno, errval)
pymysql.err.DataError: (1406, "Data too long for column 'introduceMP4' at row 1")

The above exception was the direct cause of the following exception:

Traceback (most recent call last):
  File "C:\Users\young\AppData\Local\Programs\Python\Python38\lib\site-packages\django\core\handlers\exception.py", line 47, in inner
    response = get_response(request)
  File "C:\Users\young\AppData\Local\Programs\Python\Python38\lib\site-packages\django\core\handlers\base.py", line 181, in _get_response
    response = wrapped_callback(request, *callback_args, **callback_kwargs)
  File "E:\zl\git-django-qyzs\django_wx_qhzs\polls\views.py", line 140, in add_park
    Park.objects.create(naturalLevel=naturalLevel_v, ParkLevel=ParkLevel_v,
  File "C:\Users\young\AppData\Local\Programs\Python\Python38\lib\site-packages\django\db\models\manager.py", line 85, in manager_method
    return getattr(self.get_queryset(), name)(*args, **kwargs)
  File "C:\Users\young\AppData\Local\Programs\Python\Python38\lib\site-packages\django\db\models\query.py", line 453, in create
    obj.save(force_insert=True, using=self.db)
  File "C:\Users\young\AppData\Local\Programs\Python\Python38\lib\site-packages\django\db\models\base.py", line 739, in save
    self.save_base(using=using, force_insert=force_insert,
  File "C:\Users\young\AppData\Local\Programs\Python\Python38\lib\site-packages\django\db\models\base.py", line 776, in save_base
    updated = self._save_table(
  File "C:\Users\young\AppData\Local\Programs\Python\Python38\lib\site-packages\django\db\models\base.py", line 881, in _save_table
    results = self._do_insert(cls._base_manager, using, fields, returning_fields, raw)
  File "C:\Users\young\AppData\Local\Programs\Python\Python38\lib\site-packages\django\db\models\base.py", line 919, in _do_insert
    return manager._insert(
  File "C:\Users\young\AppData\Local\Programs\Python\Python38\lib\site-packages\django\db\models\manager.py", line 85, in manager_method
    return getattr(self.get_queryset(), name)(*args, **kwargs)
  File "C:\Users\young\AppData\Local\Programs\Python\Python38\lib\site-packages\django\db\models\query.py", line 1270, in _insert
    return query.get_compiler(using=using).execute_sql(returning_fields)
  File "C:\Users\young\AppData\Local\Programs\Python\Python38\lib\site-packages\django\db\models\sql\compiler.py", line 1416, in execute_sql
    cursor.execute(sql, params)
  File "C:\Users\young\AppData\Local\Programs\Python\Python38\lib\site-packages\django\db\backends\utils.py", line 98, in execute
    return super().execute(sql, params)
  File "C:\Users\young\AppData\Local\Programs\Python\Python38\lib\site-packages\django\db\backends\utils.py", line 66, in execute
    return self._execute_with_wrappers(sql, params, many=False, executor=self._execute)
  File "C:\Users\young\AppData\Local\Programs\Python\Python38\lib\site-packages\django\db\backends\utils.py", line 75, in _execute_with_wrappers
    return executor(sql, params, many, context)
  File "C:\Users\young\AppData\Local\Programs\Python\Python38\lib\site-packages\django\db\backends\utils.py", line 84, in _execute
    return self.cursor.execute(sql, params)
  File "C:\Users\young\AppData\Local\Programs\Python\Python38\lib\site-packages\django\db\utils.py", line 90, in __exit__
    raise dj_exc_value.with_traceback(traceback) from exc_value
  File "C:\Users\young\AppData\Local\Programs\Python\Python38\lib\site-packages\django\db\backends\utils.py", line 84, in _execute
    return self.cursor.execute(sql, params)
  File "C:\Users\young\AppData\Local\Programs\Python\Python38\lib\site-packages\django\db\backends\mysql\base.py", line 73, in execute
    return self.cursor.execute(query, args)
  File "C:\Users\young\AppData\Local\Programs\Python\Python38\lib\site-packages\pymysql\cursors.py", line 148, in execute
    result = self._query(query)
  File "C:\Users\young\AppData\Local\Programs\Python\Python38\lib\site-packages\pymysql\cursors.py", line 310, in _query
    conn.query(q)
  File "C:\Users\young\AppData\Local\Programs\Python\Python38\lib\site-packages\pymysql\connections.py", line 548, in query
    self._affected_rows = self._read_query_result(unbuffered=unbuffered)
  File "C:\Users\young\AppData\Local\Programs\Python\Python38\lib\site-packages\pymysql\connections.py", line 775, in _read_query_result
    result.read()
  File "C:\Users\young\AppData\Local\Programs\Python\Python38\lib\site-packages\pymysql\connections.py", line 1156, in read
    first_packet = self.connection._read_packet()
  File "C:\Users\young\AppData\Local\Programs\Python\Python38\lib\site-packages\pymysql\connections.py", line 725, in _read_packet
    packet.raise_for_error()
  File "C:\Users\young\AppData\Local\Programs\Python\Python38\lib\site-packages\pymysql\protocol.py", line 221, in raise_for_error
    err.raise_mysql_exception(self._data)
  File "C:\Users\young\AppData\Local\Programs\Python\Python38\lib\site-packages\pymysql\err.py", line 143, in raise_mysql_exception
    raise errorclass(errno, errval)
django.db.utils.DataError: (1406, "Data too long for column 'introduceMP4' at row 1")
[2022-08-12 14:47:43,184] [basehttp.py:161] [basehttp:log_message] [ERROR]- "POST /polls/addpark/ HTTP/1.1" 500 260149
[2022-08-12 14:49:00,619] [autoreload.py:251] [autoreload:trigger_reload] [INFO]- E:\zl\git-django-qyzs\django_wx_qhzs\polls\models.py changed, reloading.
[2022-08-12 14:49:01,850] [autoreload.py:637] [autoreload:run_with_reloader] [INFO]- Watching for file changes with StatReloader
[2022-08-12 14:49:10,180] [autoreload.py:251] [autoreload:trigger_reload] [INFO]- E:\zl\git-django-qyzs\django_wx_qhzs\polls\models.py changed, reloading.
[2022-08-12 14:49:11,254] [autoreload.py:637] [autoreload:run_with_reloader] [INFO]- Watching for file changes with StatReloader
[2022-08-12 14:49:23,537] [autoreload.py:637] [autoreload:run_with_reloader] [INFO]- Watching for file changes with StatReloader
[2022-08-12 14:49:42,897] [autoreload.py:637] [autoreload:run_with_reloader] [INFO]- Watching for file changes with StatReloader
[2022-08-12 14:49:49,907] [basehttp.py:161] [basehttp:log_message] [INFO]- "GET /polls/addpark/ HTTP/1.1" 200 639
[2022-08-12 14:49:59,608] [log.py:224] [log:log_response] [ERROR]- Internal Server Error: /polls/addpark/
Traceback (most recent call last):
  File "C:\Users\young\AppData\Local\Programs\Python\Python38\lib\site-packages\django\db\backends\utils.py", line 84, in _execute
    return self.cursor.execute(sql, params)
  File "C:\Users\young\AppData\Local\Programs\Python\Python38\lib\site-packages\django\db\backends\mysql\base.py", line 73, in execute
    return self.cursor.execute(query, args)
  File "C:\Users\young\AppData\Local\Programs\Python\Python38\lib\site-packages\pymysql\cursors.py", line 148, in execute
    result = self._query(query)
  File "C:\Users\young\AppData\Local\Programs\Python\Python38\lib\site-packages\pymysql\cursors.py", line 310, in _query
    conn.query(q)
  File "C:\Users\young\AppData\Local\Programs\Python\Python38\lib\site-packages\pymysql\connections.py", line 548, in query
    self._affected_rows = self._read_query_result(unbuffered=unbuffered)
  File "C:\Users\young\AppData\Local\Programs\Python\Python38\lib\site-packages\pymysql\connections.py", line 775, in _read_query_result
    result.read()
  File "C:\Users\young\AppData\Local\Programs\Python\Python38\lib\site-packages\pymysql\connections.py", line 1156, in read
    first_packet = self.connection._read_packet()
  File "C:\Users\young\AppData\Local\Programs\Python\Python38\lib\site-packages\pymysql\connections.py", line 725, in _read_packet
    packet.raise_for_error()
  File "C:\Users\young\AppData\Local\Programs\Python\Python38\lib\site-packages\pymysql\protocol.py", line 221, in raise_for_error
    err.raise_mysql_exception(self._data)
  File "C:\Users\young\AppData\Local\Programs\Python\Python38\lib\site-packages\pymysql\err.py", line 143, in raise_mysql_exception
    raise errorclass(errno, errval)
pymysql.err.DataError: (1406, "Data too long for column 'county' at row 1")

The above exception was the direct cause of the following exception:

Traceback (most recent call last):
  File "C:\Users\young\AppData\Local\Programs\Python\Python38\lib\site-packages\django\core\handlers\exception.py", line 47, in inner
    response = get_response(request)
  File "C:\Users\young\AppData\Local\Programs\Python\Python38\lib\site-packages\django\core\handlers\base.py", line 181, in _get_response
    response = wrapped_callback(request, *callback_args, **callback_kwargs)
  File "E:\zl\git-django-qyzs\django_wx_qhzs\polls\views.py", line 140, in add_park
    Park.objects.create(naturalLevel=naturalLevel_v, ParkLevel=ParkLevel_v,
  File "C:\Users\young\AppData\Local\Programs\Python\Python38\lib\site-packages\django\db\models\manager.py", line 85, in manager_method
    return getattr(self.get_queryset(), name)(*args, **kwargs)
  File "C:\Users\young\AppData\Local\Programs\Python\Python38\lib\site-packages\django\db\models\query.py", line 453, in create
    obj.save(force_insert=True, using=self.db)
  File "C:\Users\young\AppData\Local\Programs\Python\Python38\lib\site-packages\django\db\models\base.py", line 739, in save
    self.save_base(using=using, force_insert=force_insert,
  File "C:\Users\young\AppData\Local\Programs\Python\Python38\lib\site-packages\django\db\models\base.py", line 776, in save_base
    updated = self._save_table(
  File "C:\Users\young\AppData\Local\Programs\Python\Python38\lib\site-packages\django\db\models\base.py", line 881, in _save_table
    results = self._do_insert(cls._base_manager, using, fields, returning_fields, raw)
  File "C:\Users\young\AppData\Local\Programs\Python\Python38\lib\site-packages\django\db\models\base.py", line 919, in _do_insert
    return manager._insert(
  File "C:\Users\young\AppData\Local\Programs\Python\Python38\lib\site-packages\django\db\models\manager.py", line 85, in manager_method
    return getattr(self.get_queryset(), name)(*args, **kwargs)
  File "C:\Users\young\AppData\Local\Programs\Python\Python38\lib\site-packages\django\db\models\query.py", line 1270, in _insert
    return query.get_compiler(using=using).execute_sql(returning_fields)
  File "C:\Users\young\AppData\Local\Programs\Python\Python38\lib\site-packages\django\db\models\sql\compiler.py", line 1416, in execute_sql
    cursor.execute(sql, params)
  File "C:\Users\young\AppData\Local\Programs\Python\Python38\lib\site-packages\django\db\backends\utils.py", line 98, in execute
    return super().execute(sql, params)
  File "C:\Users\young\AppData\Local\Programs\Python\Python38\lib\site-packages\django\db\backends\utils.py", line 66, in execute
    return self._execute_with_wrappers(sql, params, many=False, executor=self._execute)
  File "C:\Users\young\AppData\Local\Programs\Python\Python38\lib\site-packages\django\db\backends\utils.py", line 75, in _execute_with_wrappers
    return executor(sql, params, many, context)
  File "C:\Users\young\AppData\Local\Programs\Python\Python38\lib\site-packages\django\db\backends\utils.py", line 84, in _execute
    return self.cursor.execute(sql, params)
  File "C:\Users\young\AppData\Local\Programs\Python\Python38\lib\site-packages\django\db\utils.py", line 90, in __exit__
    raise dj_exc_value.with_traceback(traceback) from exc_value
  File "C:\Users\young\AppData\Local\Programs\Python\Python38\lib\site-packages\django\db\backends\utils.py", line 84, in _execute
    return self.cursor.execute(sql, params)
  File "C:\Users\young\AppData\Local\Programs\Python\Python38\lib\site-packages\django\db\backends\mysql\base.py", line 73, in execute
    return self.cursor.execute(query, args)
  File "C:\Users\young\AppData\Local\Programs\Python\Python38\lib\site-packages\pymysql\cursors.py", line 148, in execute
    result = self._query(query)
  File "C:\Users\young\AppData\Local\Programs\Python\Python38\lib\site-packages\pymysql\cursors.py", line 310, in _query
    conn.query(q)
  File "C:\Users\young\AppData\Local\Programs\Python\Python38\lib\site-packages\pymysql\connections.py", line 548, in query
    self._affected_rows = self._read_query_result(unbuffered=unbuffered)
  File "C:\Users\young\AppData\Local\Programs\Python\Python38\lib\site-packages\pymysql\connections.py", line 775, in _read_query_result
    result.read()
  File "C:\Users\young\AppData\Local\Programs\Python\Python38\lib\site-packages\pymysql\connections.py", line 1156, in read
    first_packet = self.connection._read_packet()
  File "C:\Users\young\AppData\Local\Programs\Python\Python38\lib\site-packages\pymysql\connections.py", line 725, in _read_packet
    packet.raise_for_error()
  File "C:\Users\young\AppData\Local\Programs\Python\Python38\lib\site-packages\pymysql\protocol.py", line 221, in raise_for_error
    err.raise_mysql_exception(self._data)
  File "C:\Users\young\AppData\Local\Programs\Python\Python38\lib\site-packages\pymysql\err.py", line 143, in raise_mysql_exception
    raise errorclass(errno, errval)
django.db.utils.DataError: (1406, "Data too long for column 'county' at row 1")
[2022-08-12 14:49:59,618] [basehttp.py:161] [basehttp:log_message] [ERROR]- "POST /polls/addpark/ HTTP/1.1" 500 263716
[2022-08-12 14:50:22,823] [autoreload.py:251] [autoreload:trigger_reload] [INFO]- E:\zl\git-django-qyzs\django_wx_qhzs\polls\models.py changed, reloading.
[2022-08-12 14:50:23,868] [autoreload.py:637] [autoreload:run_with_reloader] [INFO]- Watching for file changes with StatReloader
[2022-08-12 14:50:29,762] [autoreload.py:251] [autoreload:trigger_reload] [INFO]- E:\zl\git-django-qyzs\django_wx_qhzs\polls\models.py changed, reloading.
[2022-08-12 14:50:30,826] [autoreload.py:637] [autoreload:run_with_reloader] [INFO]- Watching for file changes with StatReloader
[2022-08-12 14:50:33,447] [autoreload.py:251] [autoreload:trigger_reload] [INFO]- E:\zl\git-django-qyzs\django_wx_qhzs\polls\models.py changed, reloading.
[2022-08-12 14:50:34,520] [autoreload.py:637] [autoreload:run_with_reloader] [INFO]- Watching for file changes with StatReloader
[2022-08-12 14:50:39,229] [autoreload.py:251] [autoreload:trigger_reload] [INFO]- E:\zl\git-django-qyzs\django_wx_qhzs\polls\models.py changed, reloading.
[2022-08-12 14:50:40,234] [autoreload.py:637] [autoreload:run_with_reloader] [INFO]- Watching for file changes with StatReloader
[2022-08-12 14:50:42,659] [autoreload.py:251] [autoreload:trigger_reload] [INFO]- E:\zl\git-django-qyzs\django_wx_qhzs\polls\models.py changed, reloading.
[2022-08-12 14:50:43,581] [autoreload.py:637] [autoreload:run_with_reloader] [INFO]- Watching for file changes with StatReloader
[2022-08-12 14:50:51,155] [autoreload.py:251] [autoreload:trigger_reload] [INFO]- E:\zl\git-django-qyzs\django_wx_qhzs\polls\models.py changed, reloading.
[2022-08-12 14:50:52,223] [autoreload.py:637] [autoreload:run_with_reloader] [INFO]- Watching for file changes with StatReloader
[2022-08-12 14:50:55,811] [autoreload.py:251] [autoreload:trigger_reload] [INFO]- E:\zl\git-django-qyzs\django_wx_qhzs\polls\models.py changed, reloading.
[2022-08-12 14:50:56,776] [autoreload.py:637] [autoreload:run_with_reloader] [INFO]- Watching for file changes with StatReloader
[2022-08-12 14:51:23,373] [autoreload.py:637] [autoreload:run_with_reloader] [INFO]- Watching for file changes with StatReloader
[2022-08-12 14:51:28,136] [basehttp.py:161] [basehttp:log_message] [INFO]- "GET /polls/addpark/ HTTP/1.1" 200 639
[2022-08-12 14:51:37,565] [basehttp.py:161] [basehttp:log_message] [INFO]- "POST /polls/addpark/ HTTP/1.1" 200 639
[2022-08-12 14:54:50,905] [autoreload.py:251] [autoreload:trigger_reload] [INFO]- E:\zl\git-django-qyzs\django_wx_qhzs\wxcloudrun\settings.py changed, reloading.
[2022-08-12 14:54:52,175] [autoreload.py:637] [autoreload:run_with_reloader] [INFO]- Watching for file changes with StatReloader
[2022-08-12 14:54:56,030] [autoreload.py:251] [autoreload:trigger_reload] [INFO]- E:\zl\git-django-qyzs\django_wx_qhzs\wxcloudrun\settings.py changed, reloading.
[2022-08-12 14:54:57,193] [autoreload.py:637] [autoreload:run_with_reloader] [INFO]- Watching for file changes with StatReloader
