[2022-08-08 01:51:19,738] [autoreload.py:637] [autoreload:run_with_reloader] [INFO]- Watching for file changes with StatReloader
[2022-08-08 02:14:59,582] [autoreload.py:637] [autoreload:run_with_reloader] [INFO]- Watching for file changes with StatReloader
[2022-08-08 10:20:09,030] [autoreload.py:637] [autoreload:run_with_reloader] [INFO]- Watching for file changes with StatReloader
[2022-08-08 11:38:23,444] [autoreload.py:637] [autoreload:run_with_reloader] [INFO]- Watching for file changes with StatReloader
[2022-08-08 11:38:44,335] [log.py:224] [log:log_response] [WARNING]- Not Found: /news/
[2022-08-08 11:38:44,336] [basehttp.py:161] [basehttp:log_message] [WARNING]- "GET /news/ HTTP/1.1" 404 2433
[2022-08-08 11:38:45,231] [log.py:224] [log:log_response] [WARNING]- Not Found: /news/
[2022-08-08 11:38:45,235] [basehttp.py:161] [basehttp:log_message] [WARNING]- "GET /news/ HTTP/1.1" 404 2433
[2022-08-08 11:38:48,467] [basehttp.py:161] [basehttp:log_message] [INFO]- "GET / HTTP/1.1" 200 10137
[2022-08-08 11:38:50,859] [views.py:40] [views:counter] [INFO]- response result: {"code": 0, "data": 3}
[2022-08-08 11:38:50,860] [basehttp.py:161] [basehttp:log_message] [INFO]- "GET /api/count HTTP/1.1" 200 22
[2022-08-08 11:38:55,294] [basehttp.py:161] [basehttp:log_message] [INFO]- "GET / HTTP/1.1" 200 10137
[2022-08-08 11:38:55,577] [views.py:40] [views:counter] [INFO]- response result: {"code": 0, "data": 3}
[2022-08-08 11:38:55,578] [basehttp.py:161] [basehttp:log_message] [INFO]- "GET /api/count HTTP/1.1" 200 22
[2022-08-08 11:39:55,990] [views.py:65] [views:update_count] [INFO]- update_count req: b'{"action":"inc"}'
[2022-08-08 11:39:56,218] [views.py:40] [views:counter] [INFO]- response result: {"code": 0, "data": 4}
[2022-08-08 11:39:56,218] [basehttp.py:161] [basehttp:log_message] [INFO]- "POST /api/count HTTP/1.1" 200 22
[2022-08-08 11:40:38,109] [basehttp.py:161] [basehttp:log_message] [INFO]- "GET /polls/ HTTP/1.1" 200 6141
[2022-08-08 11:40:41,150] [basehttp.py:161] [basehttp:log_message] [INFO]- "GET /polls/home/ HTTP/1.1" 200 9573
[2022-08-08 11:40:45,108] [basehttp.py:161] [basehttp:log_message] [INFO]- "GET /polls/Protect/ HTTP/1.1" 200 10100
[2022-08-08 11:40:48,188] [basehttp.py:161] [basehttp:log_message] [INFO]- "GET /polls/newsPosts/ HTTP/1.1" 200 8575
[2022-08-08 11:40:52,544] [basehttp.py:161] [basehttp:log_message] [INFO]- "GET /polls/HomeIMGData/ HTTP/1.1" 200 9552
[2022-08-08 11:41:09,539] [autoreload.py:251] [autoreload:trigger_reload] [INFO]- E:\zl\git-django-qyzs\django_wx_qhzs\wxcloudrun\settings.py changed, reloading.
[2022-08-08 11:41:10,788] [autoreload.py:637] [autoreload:run_with_reloader] [INFO]- Watching for file changes with StatReloader
[2022-08-08 11:41:12,730] [autoreload.py:251] [autoreload:trigger_reload] [INFO]- E:\zl\git-django-qyzs\django_wx_qhzs\wxcloudrun\settings.py changed, reloading.
[2022-08-08 11:41:13,582] [autoreload.py:637] [autoreload:run_with_reloader] [INFO]- Watching for file changes with StatReloader
[2022-08-08 04:38:39,233] [autoreload.py:637] [autoreload:run_with_reloader] [INFO]- Watching for file changes with StatReloader
[2022-08-08 13:34:31,239] [autoreload.py:637] [autoreload:run_with_reloader] [INFO]- Watching for file changes with StatReloader
[2022-08-08 13:34:35,125] [basehttp.py:161] [basehttp:log_message] [INFO]- "GET / HTTP/1.1" 200 10137
[2022-08-08 13:34:35,469] [views.py:40] [views:counter] [INFO]- response result: {"code": 0, "data": 4}
[2022-08-08 13:34:35,470] [basehttp.py:161] [basehttp:log_message] [INFO]- "GET /api/count HTTP/1.1" 200 22
[2022-08-08 13:34:49,897] [basehttp.py:161] [basehttp:log_message] [INFO]- "GET /polls/ HTTP/1.1" 200 6141
[2022-08-08 13:34:52,326] [basehttp.py:161] [basehttp:log_message] [INFO]- "GET /polls/Protect/ HTTP/1.1" 200 10100
[2022-08-08 13:34:55,862] [log.py:224] [log:log_response] [ERROR]- Internal Server Error: /polls/user/
Traceback (most recent call last):
  File "C:\Users\young\AppData\Local\Programs\Python\Python38\lib\site-packages\django\db\backends\utils.py", line 84, in _execute
    return self.cursor.execute(sql, params)
  File "C:\Users\young\AppData\Local\Programs\Python\Python38\lib\site-packages\django\db\backends\mysql\base.py", line 73, in execute
    return self.cursor.execute(query, args)
  File "C:\Users\young\AppData\Local\Programs\Python\Python38\lib\site-packages\pymysql\cursors.py", line 148, in execute
    result = self._query(query)
  File "C:\Users\young\AppData\Local\Programs\Python\Python38\lib\site-packages\pymysql\cursors.py", line 310, in _query
    conn.query(q)
  File "C:\Users\young\AppData\Local\Programs\Python\Python38\lib\site-packages\pymysql\connections.py", line 548, in query
    self._affected_rows = self._read_query_result(unbuffered=unbuffered)
  File "C:\Users\young\AppData\Local\Programs\Python\Python38\lib\site-packages\pymysql\connections.py", line 775, in _read_query_result
    result.read()
  File "C:\Users\young\AppData\Local\Programs\Python\Python38\lib\site-packages\pymysql\connections.py", line 1156, in read
    first_packet = self.connection._read_packet()
  File "C:\Users\young\AppData\Local\Programs\Python\Python38\lib\site-packages\pymysql\connections.py", line 725, in _read_packet
    packet.raise_for_error()
  File "C:\Users\young\AppData\Local\Programs\Python\Python38\lib\site-packages\pymysql\protocol.py", line 221, in raise_for_error
    err.raise_mysql_exception(self._data)
  File "C:\Users\young\AppData\Local\Programs\Python\Python38\lib\site-packages\pymysql\err.py", line 143, in raise_mysql_exception
    raise errorclass(errno, errval)
pymysql.err.ProgrammingError: (1146, "Table 'django_demo.sd_users' doesn't exist")

The above exception was the direct cause of the following exception:

Traceback (most recent call last):
  File "C:\Users\young\AppData\Local\Programs\Python\Python38\lib\site-packages\django\core\handlers\exception.py", line 47, in inner
    response = get_response(request)
  File "C:\Users\young\AppData\Local\Programs\Python\Python38\lib\site-packages\django\core\handlers\base.py", line 181, in _get_response
    response = wrapped_callback(request, *callback_args, **callback_kwargs)
  File "C:\Users\young\AppData\Local\Programs\Python\Python38\lib\site-packages\django\views\decorators\csrf.py", line 54, in wrapped_view
    return view_func(*args, **kwargs)
  File "C:\Users\young\AppData\Local\Programs\Python\Python38\lib\site-packages\rest_framework\viewsets.py", line 125, in view
    return self.dispatch(request, *args, **kwargs)
  File "C:\Users\young\AppData\Local\Programs\Python\Python38\lib\site-packages\rest_framework\views.py", line 509, in dispatch
    response = self.handle_exception(exc)
  File "C:\Users\young\AppData\Local\Programs\Python\Python38\lib\site-packages\rest_framework\views.py", line 469, in handle_exception
    self.raise_uncaught_exception(exc)
  File "C:\Users\young\AppData\Local\Programs\Python\Python38\lib\site-packages\rest_framework\views.py", line 480, in raise_uncaught_exception
    raise exc
  File "C:\Users\young\AppData\Local\Programs\Python\Python38\lib\site-packages\rest_framework\views.py", line 506, in dispatch
    response = handler(request, *args, **kwargs)
  File "C:\Users\young\AppData\Local\Programs\Python\Python38\lib\site-packages\rest_framework\mixins.py", line 46, in list
    return Response(serializer.data)
  File "C:\Users\young\AppData\Local\Programs\Python\Python38\lib\site-packages\rest_framework\serializers.py", line 768, in data
    ret = super().data
  File "C:\Users\young\AppData\Local\Programs\Python\Python38\lib\site-packages\rest_framework\serializers.py", line 253, in data
    self._data = self.to_representation(self.instance)
  File "C:\Users\young\AppData\Local\Programs\Python\Python38\lib\site-packages\rest_framework\serializers.py", line 686, in to_representation
    return [
  File "C:\Users\young\AppData\Local\Programs\Python\Python38\lib\site-packages\django\db\models\query.py", line 280, in __iter__
    self._fetch_all()
  File "C:\Users\young\AppData\Local\Programs\Python\Python38\lib\site-packages\django\db\models\query.py", line 1324, in _fetch_all
    self._result_cache = list(self._iterable_class(self))
  File "C:\Users\young\AppData\Local\Programs\Python\Python38\lib\site-packages\django\db\models\query.py", line 51, in __iter__
    results = compiler.execute_sql(chunked_fetch=self.chunked_fetch, chunk_size=self.chunk_size)
  File "C:\Users\young\AppData\Local\Programs\Python\Python38\lib\site-packages\django\db\models\sql\compiler.py", line 1175, in execute_sql
    cursor.execute(sql, params)
  File "C:\Users\young\AppData\Local\Programs\Python\Python38\lib\site-packages\django\db\backends\utils.py", line 98, in execute
    return super().execute(sql, params)
  File "C:\Users\young\AppData\Local\Programs\Python\Python38\lib\site-packages\django\db\backends\utils.py", line 66, in execute
    return self._execute_with_wrappers(sql, params, many=False, executor=self._execute)
  File "C:\Users\young\AppData\Local\Programs\Python\Python38\lib\site-packages\django\db\backends\utils.py", line 75, in _execute_with_wrappers
    return executor(sql, params, many, context)
  File "C:\Users\young\AppData\Local\Programs\Python\Python38\lib\site-packages\django\db\backends\utils.py", line 84, in _execute
    return self.cursor.execute(sql, params)
  File "C:\Users\young\AppData\Local\Programs\Python\Python38\lib\site-packages\django\db\utils.py", line 90, in __exit__
    raise dj_exc_value.with_traceback(traceback) from exc_value
  File "C:\Users\young\AppData\Local\Programs\Python\Python38\lib\site-packages\django\db\backends\utils.py", line 84, in _execute
    return self.cursor.execute(sql, params)
  File "C:\Users\young\AppData\Local\Programs\Python\Python38\lib\site-packages\django\db\backends\mysql\base.py", line 73, in execute
    return self.cursor.execute(query, args)
  File "C:\Users\young\AppData\Local\Programs\Python\Python38\lib\site-packages\pymysql\cursors.py", line 148, in execute
    result = self._query(query)
  File "C:\Users\young\AppData\Local\Programs\Python\Python38\lib\site-packages\pymysql\cursors.py", line 310, in _query
    conn.query(q)
  File "C:\Users\young\AppData\Local\Programs\Python\Python38\lib\site-packages\pymysql\connections.py", line 548, in query
    self._affected_rows = self._read_query_result(unbuffered=unbuffered)
  File "C:\Users\young\AppData\Local\Programs\Python\Python38\lib\site-packages\pymysql\connections.py", line 775, in _read_query_result
    result.read()
  File "C:\Users\young\AppData\Local\Programs\Python\Python38\lib\site-packages\pymysql\connections.py", line 1156, in read
    first_packet = self.connection._read_packet()
  File "C:\Users\young\AppData\Local\Programs\Python\Python38\lib\site-packages\pymysql\connections.py", line 725, in _read_packet
    packet.raise_for_error()
  File "C:\Users\young\AppData\Local\Programs\Python\Python38\lib\site-packages\pymysql\protocol.py", line 221, in raise_for_error
    err.raise_mysql_exception(self._data)
  File "C:\Users\young\AppData\Local\Programs\Python\Python38\lib\site-packages\pymysql\err.py", line 143, in raise_mysql_exception
    raise errorclass(errno, errval)
django.db.utils.ProgrammingError: (1146, "Table 'django_demo.sd_users' doesn't exist")
[2022-08-08 13:34:55,874] [basehttp.py:161] [basehttp:log_message] [ERROR]- "GET /polls/user/ HTTP/1.1" 500 238995
[2022-08-08 13:50:58,693] [autoreload.py:637] [autoreload:run_with_reloader] [INFO]- Watching for file changes with StatReloader
