[2022-09-17 18:31:12,698] [autoreload.py:637] [autoreload:run_with_reloader] [INFO]- Watching for file changes with StatReloader
[2022-09-17 18:32:07,282] [autoreload.py:637] [autoreload:run_with_reloader] [INFO]- Watching for file changes with StatReloader
[2022-09-17 18:32:14,582] [basehttp.py:161] [basehttp:log_message] [INFO]- "GET / HTTP/1.1" 200 6055
[2022-09-17 18:32:14,679] [basehttp.py:161] [basehttp:log_message] [INFO]- "GET /static/rest_framework/css/bootstrap-tweaks.css HTTP/1.1" 200 3385
[2022-09-17 18:32:14,681] [basehttp.py:161] [basehttp:log_message] [INFO]- "GET /static/rest_framework/css/prettify.css HTTP/1.1" 200 817
[2022-09-17 18:32:14,682] [basehttp.py:161] [basehttp:log_message] [INFO]- "GET /static/rest_framework/css/default.css HTTP/1.1" 200 1152
[2022-09-17 18:32:14,682] [basehttp.py:161] [basehttp:log_message] [INFO]- "GET /static/rest_framework/js/ajax-form.js HTTP/1.1" 200 3597
[2022-09-17 18:32:14,688] [basehttp.py:161] [basehttp:log_message] [INFO]- "GET /static/rest_framework/js/csrf.js HTTP/1.1" 200 1719
[2022-09-17 18:32:14,690] [basehttp.py:161] [basehttp:log_message] [INFO]- "GET /static/rest_framework/js/prettify-min.js HTTP/1.1" 200 13632
[2022-09-17 18:32:14,690] [basehttp.py:161] [basehttp:log_message] [INFO]- "GET /static/rest_framework/css/bootstrap.min.css HTTP/1.1" 200 121457
[2022-09-17 18:32:14,691] [basehttp.py:161] [basehttp:log_message] [INFO]- "GET /static/rest_framework/js/default.js HTTP/1.1" 200 1268
[2022-09-17 18:32:14,691] [basehttp.py:161] [basehttp:log_message] [INFO]- "GET /static/rest_framework/js/bootstrap.min.js HTTP/1.1" 200 39680
[2022-09-17 18:32:14,691] [basehttp.py:161] [basehttp:log_message] [INFO]- "GET /static/rest_framework/js/jquery-3.5.1.min.js HTTP/1.1" 200 89476
[2022-09-17 18:32:14,823] [basehttp.py:161] [basehttp:log_message] [INFO]- "GET /static/rest_framework/img/grid.png HTTP/1.1" 200 1458
[2022-09-17 18:32:15,079] [log.py:224] [log:log_response] [WARNING]- Not Found: /favicon.ico
[2022-09-17 18:32:15,081] [basehttp.py:161] [basehttp:log_message] [WARNING]- "GET /favicon.ico HTTP/1.1" 404 10571
[2022-09-17 18:32:31,474] [log.py:224] [log:log_response] [WARNING]- Not Found: /favicon.ico
[2022-09-17 18:32:31,475] [basehttp.py:161] [basehttp:log_message] [WARNING]- "GET /favicon.ico HTTP/1.1" 404 10571
[2022-09-17 18:32:32,078] [log.py:224] [log:log_response] [WARNING]- Not Found: /favicon.ico
[2022-09-17 18:32:32,079] [basehttp.py:161] [basehttp:log_message] [WARNING]- "GET /favicon.ico HTTP/1.1" 404 10571
[2022-09-17 18:32:32,680] [log.py:224] [log:log_response] [WARNING]- Not Found: /favicon.ico
[2022-09-17 18:32:32,681] [basehttp.py:161] [basehttp:log_message] [WARNING]- "GET /favicon.ico HTTP/1.1" 404 10571
[2022-09-17 18:32:57,832] [basehttp.py:161] [basehttp:log_message] [INFO]- "GET /addpark HTTP/1.1" 301 0
[2022-09-17 18:32:57,848] [basehttp.py:161] [basehttp:log_message] [INFO]- "GET /addpark/ HTTP/1.1" 200 741
[2022-09-17 18:32:57,916] [basehttp.py:161] [basehttp:log_message] [WARNING]- "GET /static/js/jquery-3.6.0.min.js HTTP/1.1" 404 1825
[2022-09-17 18:32:57,917] [basehttp.py:161] [basehttp:log_message] [INFO]- "GET /static/js/bootstrap.min.js HTTP/1.1" 200 39680
[2022-09-17 18:32:57,918] [basehttp.py:161] [basehttp:log_message] [INFO]- "GET /static/css/bootstrap.min.css HTTP/1.1" 200 121457
[2022-09-17 18:32:57,999] [basehttp.py:161] [basehttp:log_message] [WARNING]- "GET /static/js/jquery-3.6.0.min.js HTTP/1.1" 404 1825
[2022-09-17 18:33:05,437] [log.py:224] [log:log_response] [ERROR]- Internal Server Error: /addpark/
Traceback (most recent call last):
  File "C:\Users\young\AppData\Local\Programs\Python\Python38\lib\site-packages\django\db\backends\utils.py", line 84, in _execute
    return self.cursor.execute(sql, params)
  File "C:\Users\young\AppData\Local\Programs\Python\Python38\lib\site-packages\django\db\backends\mysql\base.py", line 73, in execute
    return self.cursor.execute(query, args)
  File "C:\Users\young\AppData\Local\Programs\Python\Python38\lib\site-packages\pymysql\cursors.py", line 148, in execute
    result = self._query(query)
  File "C:\Users\young\AppData\Local\Programs\Python\Python38\lib\site-packages\pymysql\cursors.py", line 310, in _query
    conn.query(q)
  File "C:\Users\young\AppData\Local\Programs\Python\Python38\lib\site-packages\pymysql\connections.py", line 548, in query
    self._affected_rows = self._read_query_result(unbuffered=unbuffered)
  File "C:\Users\young\AppData\Local\Programs\Python\Python38\lib\site-packages\pymysql\connections.py", line 775, in _read_query_result
    result.read()
  File "C:\Users\young\AppData\Local\Programs\Python\Python38\lib\site-packages\pymysql\connections.py", line 1156, in read
    first_packet = self.connection._read_packet()
  File "C:\Users\young\AppData\Local\Programs\Python\Python38\lib\site-packages\pymysql\connections.py", line 725, in _read_packet
    packet.raise_for_error()
  File "C:\Users\young\AppData\Local\Programs\Python\Python38\lib\site-packages\pymysql\protocol.py", line 221, in raise_for_error
    err.raise_mysql_exception(self._data)
  File "C:\Users\young\AppData\Local\Programs\Python\Python38\lib\site-packages\pymysql\err.py", line 143, in raise_mysql_exception
    raise errorclass(errno, errval)
pymysql.err.DataError: (1406, "Data too long for column 'icon' at row 1")

The above exception was the direct cause of the following exception:

Traceback (most recent call last):
  File "C:\Users\young\AppData\Local\Programs\Python\Python38\lib\site-packages\django\core\handlers\exception.py", line 47, in inner
    response = get_response(request)
  File "C:\Users\young\AppData\Local\Programs\Python\Python38\lib\site-packages\django\core\handlers\base.py", line 181, in _get_response
    response = wrapped_callback(request, *callback_args, **callback_kwargs)
  File "E:\zl\git-django-qyzs\django_wx_qhzs\polls\views.py", line 168, in add_park
    Park.objects.create(naturalLevel=naturalLevel_v, ParkLevel=ParkLevel_v,
  File "C:\Users\young\AppData\Local\Programs\Python\Python38\lib\site-packages\django\db\models\manager.py", line 85, in manager_method
    return getattr(self.get_queryset(), name)(*args, **kwargs)
  File "C:\Users\young\AppData\Local\Programs\Python\Python38\lib\site-packages\django\db\models\query.py", line 453, in create
    obj.save(force_insert=True, using=self.db)
  File "C:\Users\young\AppData\Local\Programs\Python\Python38\lib\site-packages\django\db\models\base.py", line 739, in save
    self.save_base(using=using, force_insert=force_insert,
  File "C:\Users\young\AppData\Local\Programs\Python\Python38\lib\site-packages\django\db\models\base.py", line 776, in save_base
    updated = self._save_table(
  File "C:\Users\young\AppData\Local\Programs\Python\Python38\lib\site-packages\django\db\models\base.py", line 881, in _save_table
    results = self._do_insert(cls._base_manager, using, fields, returning_fields, raw)
  File "C:\Users\young\AppData\Local\Programs\Python\Python38\lib\site-packages\django\db\models\base.py", line 919, in _do_insert
    return manager._insert(
  File "C:\Users\young\AppData\Local\Programs\Python\Python38\lib\site-packages\django\db\models\manager.py", line 85, in manager_method
    return getattr(self.get_queryset(), name)(*args, **kwargs)
  File "C:\Users\young\AppData\Local\Programs\Python\Python38\lib\site-packages\django\db\models\query.py", line 1270, in _insert
    return query.get_compiler(using=using).execute_sql(returning_fields)
  File "C:\Users\young\AppData\Local\Programs\Python\Python38\lib\site-packages\django\db\models\sql\compiler.py", line 1416, in execute_sql
    cursor.execute(sql, params)
  File "C:\Users\young\AppData\Local\Programs\Python\Python38\lib\site-packages\django\db\backends\utils.py", line 98, in execute
    return super().execute(sql, params)
  File "C:\Users\young\AppData\Local\Programs\Python\Python38\lib\site-packages\django\db\backends\utils.py", line 66, in execute
    return self._execute_with_wrappers(sql, params, many=False, executor=self._execute)
  File "C:\Users\young\AppData\Local\Programs\Python\Python38\lib\site-packages\django\db\backends\utils.py", line 75, in _execute_with_wrappers
    return executor(sql, params, many, context)
  File "C:\Users\young\AppData\Local\Programs\Python\Python38\lib\site-packages\django\db\backends\utils.py", line 84, in _execute
    return self.cursor.execute(sql, params)
  File "C:\Users\young\AppData\Local\Programs\Python\Python38\lib\site-packages\django\db\utils.py", line 90, in __exit__
    raise dj_exc_value.with_traceback(traceback) from exc_value
  File "C:\Users\young\AppData\Local\Programs\Python\Python38\lib\site-packages\django\db\backends\utils.py", line 84, in _execute
    return self.cursor.execute(sql, params)
  File "C:\Users\young\AppData\Local\Programs\Python\Python38\lib\site-packages\django\db\backends\mysql\base.py", line 73, in execute
    return self.cursor.execute(query, args)
  File "C:\Users\young\AppData\Local\Programs\Python\Python38\lib\site-packages\pymysql\cursors.py", line 148, in execute
    result = self._query(query)
  File "C:\Users\young\AppData\Local\Programs\Python\Python38\lib\site-packages\pymysql\cursors.py", line 310, in _query
    conn.query(q)
  File "C:\Users\young\AppData\Local\Programs\Python\Python38\lib\site-packages\pymysql\connections.py", line 548, in query
    self._affected_rows = self._read_query_result(unbuffered=unbuffered)
  File "C:\Users\young\AppData\Local\Programs\Python\Python38\lib\site-packages\pymysql\connections.py", line 775, in _read_query_result
    result.read()
  File "C:\Users\young\AppData\Local\Programs\Python\Python38\lib\site-packages\pymysql\connections.py", line 1156, in read
    first_packet = self.connection._read_packet()
  File "C:\Users\young\AppData\Local\Programs\Python\Python38\lib\site-packages\pymysql\connections.py", line 725, in _read_packet
    packet.raise_for_error()
  File "C:\Users\young\AppData\Local\Programs\Python\Python38\lib\site-packages\pymysql\protocol.py", line 221, in raise_for_error
    err.raise_mysql_exception(self._data)
  File "C:\Users\young\AppData\Local\Programs\Python\Python38\lib\site-packages\pymysql\err.py", line 143, in raise_mysql_exception
    raise errorclass(errno, errval)
django.db.utils.DataError: (1406, "Data too long for column 'icon' at row 1")
[2022-09-17 18:33:05,447] [basehttp.py:161] [basehttp:log_message] [ERROR]- "POST /addpark/ HTTP/1.1" 500 351069
[2022-09-17 18:35:26,403] [autoreload.py:637] [autoreload:run_with_reloader] [INFO]- Watching for file changes with StatReloader
[2022-09-17 18:35:44,852] [autoreload.py:637] [autoreload:run_with_reloader] [INFO]- Watching for file changes with StatReloader
[2022-09-17 18:35:50,326] [basehttp.py:161] [basehttp:log_message] [INFO]- "GET /addpark/ HTTP/1.1" 200 741
[2022-09-17 18:35:50,396] [basehttp.py:161] [basehttp:log_message] [WARNING]- "GET /static/js/jquery-3.6.0.min.js HTTP/1.1" 404 1825
[2022-09-17 18:35:50,473] [basehttp.py:161] [basehttp:log_message] [WARNING]- "GET /static/js/jquery-3.6.0.min.js HTTP/1.1" 404 1825
[2022-09-17 18:35:59,082] [basehttp.py:161] [basehttp:log_message] [INFO]- "POST /addpark/ HTTP/1.1" 200 741
[2022-09-17 18:35:59,145] [basehttp.py:161] [basehttp:log_message] [WARNING]- "GET /static/js/jquery-3.6.0.min.js HTTP/1.1" 404 1825
[2022-09-17 18:35:59,222] [basehttp.py:161] [basehttp:log_message] [WARNING]- "GET /static/js/jquery-3.6.0.min.js HTTP/1.1" 404 1825
[2022-09-17 18:43:28,081] [basehttp.py:161] [basehttp:log_message] [INFO]- "POST /addpark/ HTTP/1.1" 200 741
[2022-09-17 18:43:28,167] [basehttp.py:161] [basehttp:log_message] [WARNING]- "GET /static/js/jquery-3.6.0.min.js HTTP/1.1" 404 1825
[2022-09-17 18:43:28,248] [basehttp.py:161] [basehttp:log_message] [WARNING]- "GET /static/js/jquery-3.6.0.min.js HTTP/1.1" 404 1825
[2022-09-17 18:45:41,345] [basehttp.py:161] [basehttp:log_message] [INFO]- "POST /addpark/ HTTP/1.1" 200 741
[2022-09-17 18:45:41,398] [basehttp.py:161] [basehttp:log_message] [WARNING]- "GET /static/js/jquery-3.6.0.min.js HTTP/1.1" 404 1825
[2022-09-17 18:45:41,474] [basehttp.py:161] [basehttp:log_message] [WARNING]- "GET /static/js/jquery-3.6.0.min.js HTTP/1.1" 404 1825
[2022-09-17 18:46:12,447] [log.py:224] [log:log_response] [ERROR]- Internal Server Error: /addpark/
Traceback (most recent call last):
  File "C:\Users\young\AppData\Local\Programs\Python\Python38\lib\site-packages\django\db\backends\utils.py", line 84, in _execute
    return self.cursor.execute(sql, params)
  File "C:\Users\young\AppData\Local\Programs\Python\Python38\lib\site-packages\django\db\backends\mysql\base.py", line 73, in execute
    return self.cursor.execute(query, args)
  File "C:\Users\young\AppData\Local\Programs\Python\Python38\lib\site-packages\pymysql\cursors.py", line 148, in execute
    result = self._query(query)
  File "C:\Users\young\AppData\Local\Programs\Python\Python38\lib\site-packages\pymysql\cursors.py", line 310, in _query
    conn.query(q)
  File "C:\Users\young\AppData\Local\Programs\Python\Python38\lib\site-packages\pymysql\connections.py", line 548, in query
    self._affected_rows = self._read_query_result(unbuffered=unbuffered)
  File "C:\Users\young\AppData\Local\Programs\Python\Python38\lib\site-packages\pymysql\connections.py", line 775, in _read_query_result
    result.read()
  File "C:\Users\young\AppData\Local\Programs\Python\Python38\lib\site-packages\pymysql\connections.py", line 1156, in read
    first_packet = self.connection._read_packet()
  File "C:\Users\young\AppData\Local\Programs\Python\Python38\lib\site-packages\pymysql\connections.py", line 725, in _read_packet
    packet.raise_for_error()
  File "C:\Users\young\AppData\Local\Programs\Python\Python38\lib\site-packages\pymysql\protocol.py", line 221, in raise_for_error
    err.raise_mysql_exception(self._data)
  File "C:\Users\young\AppData\Local\Programs\Python\Python38\lib\site-packages\pymysql\err.py", line 143, in raise_mysql_exception
    raise errorclass(errno, errval)
pymysql.err.IntegrityError: (1048, "Column 'introduceEN' cannot be null")

The above exception was the direct cause of the following exception:

Traceback (most recent call last):
  File "C:\Users\young\AppData\Local\Programs\Python\Python38\lib\site-packages\django\core\handlers\exception.py", line 47, in inner
    response = get_response(request)
  File "C:\Users\young\AppData\Local\Programs\Python\Python38\lib\site-packages\django\core\handlers\base.py", line 181, in _get_response
    response = wrapped_callback(request, *callback_args, **callback_kwargs)
  File "E:\zl\git-django-qyzs\django_wx_qhzs\polls\views.py", line 180, in add_park
    Park.objects.filter(name1=name1_v).update(naturalLevel=naturalLevel_v, ParkLevel=ParkLevel_v,
  File "C:\Users\young\AppData\Local\Programs\Python\Python38\lib\site-packages\django\db\models\query.py", line 783, in update
    rows = query.get_compiler(self.db).execute_sql(CURSOR)
  File "C:\Users\young\AppData\Local\Programs\Python\Python38\lib\site-packages\django\db\models\sql\compiler.py", line 1559, in execute_sql
    cursor = super().execute_sql(result_type)
  File "C:\Users\young\AppData\Local\Programs\Python\Python38\lib\site-packages\django\db\models\sql\compiler.py", line 1175, in execute_sql
    cursor.execute(sql, params)
  File "C:\Users\young\AppData\Local\Programs\Python\Python38\lib\site-packages\django\db\backends\utils.py", line 98, in execute
    return super().execute(sql, params)
  File "C:\Users\young\AppData\Local\Programs\Python\Python38\lib\site-packages\django\db\backends\utils.py", line 66, in execute
    return self._execute_with_wrappers(sql, params, many=False, executor=self._execute)
  File "C:\Users\young\AppData\Local\Programs\Python\Python38\lib\site-packages\django\db\backends\utils.py", line 75, in _execute_with_wrappers
    return executor(sql, params, many, context)
  File "C:\Users\young\AppData\Local\Programs\Python\Python38\lib\site-packages\django\db\backends\utils.py", line 84, in _execute
    return self.cursor.execute(sql, params)
  File "C:\Users\young\AppData\Local\Programs\Python\Python38\lib\site-packages\django\db\utils.py", line 90, in __exit__
    raise dj_exc_value.with_traceback(traceback) from exc_value
  File "C:\Users\young\AppData\Local\Programs\Python\Python38\lib\site-packages\django\db\backends\utils.py", line 84, in _execute
    return self.cursor.execute(sql, params)
  File "C:\Users\young\AppData\Local\Programs\Python\Python38\lib\site-packages\django\db\backends\mysql\base.py", line 73, in execute
    return self.cursor.execute(query, args)
  File "C:\Users\young\AppData\Local\Programs\Python\Python38\lib\site-packages\pymysql\cursors.py", line 148, in execute
    result = self._query(query)
  File "C:\Users\young\AppData\Local\Programs\Python\Python38\lib\site-packages\pymysql\cursors.py", line 310, in _query
    conn.query(q)
  File "C:\Users\young\AppData\Local\Programs\Python\Python38\lib\site-packages\pymysql\connections.py", line 548, in query
    self._affected_rows = self._read_query_result(unbuffered=unbuffered)
  File "C:\Users\young\AppData\Local\Programs\Python\Python38\lib\site-packages\pymysql\connections.py", line 775, in _read_query_result
    result.read()
  File "C:\Users\young\AppData\Local\Programs\Python\Python38\lib\site-packages\pymysql\connections.py", line 1156, in read
    first_packet = self.connection._read_packet()
  File "C:\Users\young\AppData\Local\Programs\Python\Python38\lib\site-packages\pymysql\connections.py", line 725, in _read_packet
    packet.raise_for_error()
  File "C:\Users\young\AppData\Local\Programs\Python\Python38\lib\site-packages\pymysql\protocol.py", line 221, in raise_for_error
    err.raise_mysql_exception(self._data)
  File "C:\Users\young\AppData\Local\Programs\Python\Python38\lib\site-packages\pymysql\err.py", line 143, in raise_mysql_exception
    raise errorclass(errno, errval)
django.db.utils.IntegrityError: (1048, "Column 'introduceEN' cannot be null")
[2022-09-17 18:46:12,463] [basehttp.py:161] [basehttp:log_message] [ERROR]- "POST /addpark/ HTTP/1.1" 500 267606
[2022-09-17 18:46:51,702] [basehttp.py:161] [basehttp:log_message] [INFO]- "GET /addpark/ HTTP/1.1" 200 741
[2022-09-17 18:46:51,774] [basehttp.py:161] [basehttp:log_message] [WARNING]- "GET /static/js/jquery-3.6.0.min.js HTTP/1.1" 404 1825
[2022-09-17 18:46:51,852] [basehttp.py:161] [basehttp:log_message] [WARNING]- "GET /static/js/jquery-3.6.0.min.js HTTP/1.1" 404 1825
[2022-09-17 18:47:04,272] [basehttp.py:161] [basehttp:log_message] [INFO]- "POST /addpark/ HTTP/1.1" 200 741
[2022-09-17 18:47:04,347] [basehttp.py:161] [basehttp:log_message] [WARNING]- "GET /static/js/jquery-3.6.0.min.js HTTP/1.1" 404 1825
[2022-09-17 18:47:04,415] [basehttp.py:161] [basehttp:log_message] [WARNING]- "GET /static/js/jquery-3.6.0.min.js HTTP/1.1" 404 1825
[2022-09-17 19:05:21,208] [basehttp.py:161] [basehttp:log_message] [INFO]- "POST /addpark/ HTTP/1.1" 200 741
[2022-09-17 19:05:21,274] [basehttp.py:161] [basehttp:log_message] [WARNING]- "GET /static/js/jquery-3.6.0.min.js HTTP/1.1" 404 1825
[2022-09-17 19:05:21,361] [basehttp.py:161] [basehttp:log_message] [WARNING]- "GET /static/js/jquery-3.6.0.min.js HTTP/1.1" 404 1825
[2022-09-17 19:47:59,118] [basehttp.py:161] [basehttp:log_message] [INFO]- "POST /addpark/ HTTP/1.1" 200 741
[2022-09-17 19:47:59,205] [basehttp.py:161] [basehttp:log_message] [WARNING]- "GET /static/js/jquery-3.6.0.min.js HTTP/1.1" 404 1825
[2022-09-17 19:47:59,282] [basehttp.py:161] [basehttp:log_message] [WARNING]- "GET /static/js/jquery-3.6.0.min.js HTTP/1.1" 404 1825
[2022-09-17 19:50:48,241] [log.py:224] [log:log_response] [ERROR]- Internal Server Error: /addpark/
Traceback (most recent call last):
  File "C:\Users\young\AppData\Local\Programs\Python\Python38\lib\site-packages\django\core\handlers\exception.py", line 47, in inner
    response = get_response(request)
  File "C:\Users\young\AppData\Local\Programs\Python\Python38\lib\site-packages\django\core\handlers\base.py", line 181, in _get_response
    response = wrapped_callback(request, *callback_args, **callback_kwargs)
  File "E:\zl\git-django-qyzs\django_wx_qhzs\polls\views.py", line 149, in add_park
    icon_v = json.loads(row[6].value)
  File "C:\Users\young\AppData\Local\Programs\Python\Python38\lib\json\__init__.py", line 341, in loads
    raise TypeError(f'the JSON object must be str, bytes or bytearray, '
TypeError: the JSON object must be str, bytes or bytearray, not NoneType
[2022-09-17 19:50:48,245] [basehttp.py:161] [basehttp:log_message] [ERROR]- "POST /addpark/ HTTP/1.1" 500 84283
[2022-09-17 19:59:15,382] [autoreload.py:251] [autoreload:trigger_reload] [INFO]- E:\zl\git-django-qyzs\django_wx_qhzs\wxcloudrun\settings.py changed, reloading.
[2022-09-17 19:59:16,983] [autoreload.py:637] [autoreload:run_with_reloader] [INFO]- Watching for file changes with StatReloader
[2022-09-17 20:36:25,447] [autoreload.py:251] [autoreload:trigger_reload] [INFO]- E:\zl\git-django-qyzs\django_wx_qhzs\polls\views.py changed, reloading.
[2022-09-17 20:36:26,319] [autoreload.py:637] [autoreload:run_with_reloader] [INFO]- Watching for file changes with StatReloader
[2022-09-17 20:36:56,373] [autoreload.py:251] [autoreload:trigger_reload] [INFO]- E:\zl\git-django-qyzs\django_wx_qhzs\polls\views.py changed, reloading.
[2022-09-17 20:36:57,301] [autoreload.py:637] [autoreload:run_with_reloader] [INFO]- Watching for file changes with StatReloader
[2022-09-17 20:37:30,903] [autoreload.py:251] [autoreload:trigger_reload] [INFO]- E:\zl\git-django-qyzs\django_wx_qhzs\polls\views.py changed, reloading.
[2022-09-17 20:37:31,851] [autoreload.py:637] [autoreload:run_with_reloader] [INFO]- Watching for file changes with StatReloader
[2022-09-17 20:37:48,612] [autoreload.py:251] [autoreload:trigger_reload] [INFO]- E:\zl\git-django-qyzs\django_wx_qhzs\wxcloudrun\settings.py changed, reloading.
[2022-09-17 20:37:49,482] [autoreload.py:637] [autoreload:run_with_reloader] [INFO]- Watching for file changes with StatReloader
[2022-09-17 20:37:56,111] [basehttp.py:161] [basehttp:log_message] [INFO]- code 400, message Bad request version ('x\x02\x1aØ')
[2022-09-17 20:37:56,112] [basehttp.py:142] [basehttp:log_message] [ERROR]- You're accessing the development server over HTTPS, but it only supports HTTP.

[2022-09-17 20:37:56,115] [basehttp.py:161] [basehttp:log_message] [INFO]- code 400, message Bad request version ('êê\x13\x01\x13\x02\x13\x03À+À/À,À0Ì©Ì¨À\x13À\x14\x00\x9c\x00\x9d\x00/\x005\x01\x00\x01\x93')
[2022-09-17 20:37:56,116] [basehttp.py:142] [basehttp:log_message] [ERROR]- You're accessing the development server over HTTPS, but it only supports HTTP.

[2022-09-17 20:37:56,159] [basehttp.py:161] [basehttp:log_message] [INFO]- "GET / HTTP/1.1" 200 6021
[2022-09-17 20:37:56,191] [basehttp.py:161] [basehttp:log_message] [INFO]- "GET /static/rest_framework/css/prettify.css HTTP/1.1" 200 817
[2022-09-17 20:37:56,194] [basehttp.py:161] [basehttp:log_message] [INFO]- "GET /static/rest_framework/css/bootstrap-tweaks.css HTTP/1.1" 200 3385
[2022-09-17 20:37:56,202] [basehttp.py:161] [basehttp:log_message] [INFO]- "GET /static/rest_framework/css/bootstrap.min.css HTTP/1.1" 200 121457
[2022-09-17 20:37:56,203] [basehttp.py:161] [basehttp:log_message] [INFO]- "GET /static/rest_framework/css/default.css HTTP/1.1" 200 1152
[2022-09-17 20:37:56,206] [basehttp.py:161] [basehttp:log_message] [INFO]- "GET /static/rest_framework/js/csrf.js HTTP/1.1" 200 1719
[2022-09-17 20:37:56,208] [basehttp.py:161] [basehttp:log_message] [INFO]- "GET /static/rest_framework/js/bootstrap.min.js HTTP/1.1" 200 39680
[2022-09-17 20:37:56,208] [basehttp.py:161] [basehttp:log_message] [INFO]- "GET /static/rest_framework/js/prettify-min.js HTTP/1.1" 200 13632
[2022-09-17 20:37:56,209] [basehttp.py:161] [basehttp:log_message] [INFO]- "GET /static/rest_framework/js/ajax-form.js HTTP/1.1" 200 3597
[2022-09-17 20:37:56,211] [basehttp.py:161] [basehttp:log_message] [INFO]- "GET /static/rest_framework/js/jquery-3.5.1.min.js HTTP/1.1" 200 89476
[2022-09-17 20:37:56,221] [basehttp.py:161] [basehttp:log_message] [INFO]- "GET /static/rest_framework/js/default.js HTTP/1.1" 200 1268
[2022-09-17 20:37:56,240] [basehttp.py:161] [basehttp:log_message] [INFO]- "GET /static/rest_framework/img/grid.png HTTP/1.1" 200 1458
[2022-09-17 20:37:56,391] [log.py:224] [log:log_response] [WARNING]- Not Found: /favicon.ico
[2022-09-17 20:37:56,392] [basehttp.py:161] [basehttp:log_message] [WARNING]- "GET /favicon.ico HTTP/1.1" 404 10571
[2022-09-17 20:38:15,355] [basehttp.py:161] [basehttp:log_message] [INFO]- "GET /addpark HTTP/1.1" 301 0
[2022-09-17 20:38:15,361] [basehttp.py:161] [basehttp:log_message] [INFO]- "GET /addpark/ HTTP/1.1" 200 741
[2022-09-17 20:38:15,393] [basehttp.py:161] [basehttp:log_message] [WARNING]- "GET /static/js/jquery-3.6.0.min.js HTTP/1.1" 404 1825
[2022-09-17 20:38:15,394] [basehttp.py:161] [basehttp:log_message] [INFO]- "GET /static/js/bootstrap.min.js HTTP/1.1" 200 39680
[2022-09-17 20:38:15,395] [basehttp.py:161] [basehttp:log_message] [INFO]- "GET /static/css/bootstrap.min.css HTTP/1.1" 200 121457
[2022-09-17 20:38:26,265] [basehttp.py:161] [basehttp:log_message] [INFO]- "POST /addpark/ HTTP/1.1" 200 741
[2022-09-17 20:38:26,286] [basehttp.py:161] [basehttp:log_message] [WARNING]- "GET /static/js/jquery-3.6.0.min.js HTTP/1.1" 404 1825
[2022-09-17 20:41:45,072] [autoreload.py:637] [autoreload:run_with_reloader] [INFO]- Watching for file changes with StatReloader
[2022-09-17 20:42:07,485] [basehttp.py:161] [basehttp:log_message] [INFO]- "GET / HTTP/1.1" 200 6021
[2022-09-17 20:42:07,719] [log.py:224] [log:log_response] [WARNING]- Not Found: /favicon.ico
[2022-09-17 20:42:07,720] [basehttp.py:161] [basehttp:log_message] [WARNING]- "GET /favicon.ico HTTP/1.1" 404 10571
[2022-09-17 20:42:21,333] [basehttp.py:161] [basehttp:log_message] [INFO]- "POST /addpark/ HTTP/1.1" 200 741
[2022-09-17 20:42:21,350] [basehttp.py:161] [basehttp:log_message] [WARNING]- "GET /static/js/jquery-3.6.0.min.js HTTP/1.1" 404 1825
[2022-09-19 08:59:44,984] [autoreload.py:251] [autoreload:trigger_reload] [INFO]- E:\zl\git-django-qyzs\django_wx_qhzs\polls\views.py changed, reloading.
